Workbook
Name CONCEPTO: DETALLADO!$C$3:$C$61
Name CONCEPTOS: DETALLADO!$B$3:$B$61
Name PRO: PROVEEDORES!$B$2:$B$197
Name PROV: PROVEEDORES!#REF!
Name PROVEEDORES: PROVEEDORES!$B$2:$B$450
Name V.: DETALLADO!$C$3:$C$61

Sheet 1
A1: =1 -> 1 | B1: QUESO Y CAFÉ | D1: 46143 | G1: CUADRE DE CAJA MAÑANA | I1: CUADRE DE CAJA TARDE
A2: NIT | B2: PROVEEDOR | C2: CONCEPTO | D2: DESCRIPCIÓN | E2: VALOR | G2: PROP. TRANSF.: | H2: 0 | I2: PROP. TRANSF.: | J2: 0
A3: =IF(B3="","",VLOOKUP(B3,PROVEEDORES!$B:$C,2,FALSE)) | E3: 0 | G3: PROP. BANCO: | H3: 0 | I3: PROP. BANCO: | J3: 0
A4: =IF(B4="","",VLOOKUP(B4,PROVEEDORES!$B:$C,2,FALSE)) | E4: 0 | G4: PROP. EFECTIVO: | H4: 0 | I4: PROP. EFECTIVO: | J4: 0
A5: =IF(B5="","",VLOOKUP(B5,PROVEEDORES!$B:$C,2,FALSE)) | E5: 0 | G5: GASTO: | H5: 0 | I5: GASTO: | J5: 0
A6: =IF(B6="","",VLOOKUP(B6,PROVEEDORES!$B:$C,2,FALSE)) | E6: 0 | G6: TRANSFERENCIA: | H6: 0 | I6: TRANSFERENCIA: | J6: 0
A7: =IF(B7="","",VLOOKUP(B7,PROVEEDORES!$B:$C,2,FALSE)) | E7: 0 | G7: BANCO: | H7: 0 | I7: BANCO: | J7: 0
A8: =IF(B8="","",VLOOKUP(B8,PROVEEDORES!$B:$C,2,FALSE)) | E8: 0 | G8: EFECTIVO: | H8: 0 | I8: EFECTIVO: | J8: 0
A9: =IF(B9="","",VLOOKUP(B9,PROVEEDORES!$B:$C,2,FALSE)) | E9: 0 | G9: TOTAL: | H9: =SUM(H5:H8) -> 0 | I9: TOTAL: | J9: =SUM(J5:J8) -> 0
A10: =IF(B10="","",VLOOKUP(B10,PROVEEDORES!$B:$C,2,FALSE)) | E10: 0 | G10: DIFERENCIA: | H10: =+H11-H9 -> 0 | I10: DIFERENCIA: | J10: =+J11-J9 -> 0
A11: =IF(B11="","",VLOOKUP(B11,PROVEEDORES!$B:$C,2,FALSE)) | E11: 0 | G11: TOTAL VENTA: | H11: 0 | I11: TOTAL VENTA: | J11: 0
A12: =IF(B12="","",VLOOKUP(B12,PROVEEDORES!$B:$C,2,FALSE)) | E12: 0
A13: PROPINA TRANSFERENCIA: | C13: =SUM(H2,J2) -> 0 | D13: ACUM. PROPINA TRANFERENCIA: | E13: =SUM(C13,I37)-C57 -> 0 | G13: DIFERENCIA PLANILLA VS CUADRE DE CAJA | I13: =+C20-(SUM(H9,J9)) -> 0
A14: PROPINA POR BANCO: | C14: =SUM(H3,J3) -> 0 | D14: ACUM. PROPINA BANCO: | E14: =SUM(C14,I38)-C58 -> 0
A15: PROPINA EN EFECTIVO: | C15: =SUM(H4,J4) -> 0 | D15: ACUM. PROPINA EFECTIVO: | E15: =SUM(C15,I39)-C59 -> 0 | G15: FACTURAS EN EFECTIVO: | I15: 0
A16: TOTAL EGRESOS: | C16: =SUM(E3:E12) -> 0 | D16: ACUMULADO TRANSFERENCIA: | E16: =SUM(C17,I40) -> 0 | G16: EFECTIVO: | I16: 0
A17: TRANSFERENCIA: | C17: =SUM(H6,J6) -> 0 | D17: ACUMULADO BANCO: | E17: =SUM(C18,I41) -> 0 | G17: TOTAL EFECTIVO REAL ACTUAL: | I17: =SUM(I15,I16) -> 0
A18: BANCO: | C18: =SUM(H7,J7) -> 0 | D18: TOTAL BANCO: | E18: =SUM(C18,I42)-(SUM(E36:E55)) -> 0 | G18: DIFERENCIA: | I18: =+I19-I17 -> 0
A19: EFECTIVO: | C19: =SUM(H8,J8) -> 0 | D19: TOTAL EFECTIVO: | E19: =SUM(C19,E20,E57:E59)-(SUM(E23:E34)) -> 0 | G19: EFECTIVO ACTUAL PLANILLA: | I19: =E19 -> 0
A20: TOTAL VENTA: | C20: =SUM(C16:C19) -> 0 | D20: EFECTIVO ANTERIOR: | E20: =+I43 -> 0
A21: EGRESO DE CAJA MAYOR | G21: CONTEO DE EFECTIVO
A22: NIT | B22: PROVEEDOR | C22: CONCEPTO | D22: DESCRIPCIÓN | E22: EFECTIVO | G22: DENOMINACIÓN | H22: CANTIDAD | I22: EFECTIVO
A23: =IF(B23="","",VLOOKUP(B23,PROVEEDORES!$B:$C,2,FALSE)) | E23: 0 | G23: MONEDAS DE 100 | H23: 0 | I23: =100*H23 -> 0
A24: =IF(B24="","",VLOOKUP(B24,PROVEEDORES!$B:$C,2,FALSE)) | E24: 0 | G24: MONEDAS DE 200 | H24: 0 | I24: =200*H24 -> 0
A25: =IF(B25="","",VLOOKUP(B25,PROVEEDORES!$B:$C,2,FALSE)) | E25: 0 | G25: MONEDAS DE 500 | H25: 0 | I25: =500*H25 -> 0
A26: =IF(B26="","",VLOOKUP(B26,PROVEEDORES!$B:$C,2,FALSE)) | E26: 0 | G26: MONEDAS DE 1.000 | H26: 0 | I26: =1000*H26 -> 0
A27: =IF(B27="","",VLOOKUP(B27,PROVEEDORES!$B:$C,2,FALSE)) | E27: 0 | G27: BILLETES DE 2.000 | H27: 0 | I27: =2000*H27 -> 0
A28: =IF(B28="","",VLOOKUP(B28,PROVEEDORES!$B:$C,2,FALSE)) | E28: 0 | G28: BILLETES DE 5.000 | H28: 0 | I28: =5000*H28 -> 0
A29: =IF(B29="","",VLOOKUP(B29,PROVEEDORES!$B:$C,2,FALSE)) | E29: 0 | G29: BILLETES DE 10.000 | H29: 0 | I29: =10000*H29 -> 0
A30: =IF(B30="","",VLOOKUP(B30,PROVEEDORES!$B:$C,2,FALSE)) | E30: 0 | G30: BILLETES DE 20.000 | H30: 0 | I30: =20000*H30 -> 0
A31: =IF(B31="","",VLOOKUP(B31,PROVEEDORES!$B:$C,2,FALSE)) | E31: 0 | G31: BILLETES DE 50.000 | H31: 0 | I31: =50000*H31 -> 0
A32: =IF(B32="","",VLOOKUP(B32,PROVEEDORES!$B:$C,2,FALSE)) | E32: 0 | G32: BILLETES DE 100.000 | H32: 0 | I32: =100000*H32 -> 0
A33: =IF(B33="","",VLOOKUP(B33,PROVEEDORES!$B:$C,2,FALSE)) | E33: 0 | G33: TOTAL EFECTIVO: | I33: =SUM(I23:I32) -> 0
A34: =IF(B34="","",VLOOKUP(B34,PROVEEDORES!$B:$C,2,FALSE)) | E34: 0 | G34: BASE: | I34: 0
A35: NIT | B35: PROVEEDOR | C35: CONCEPTO | D35: DESCRIPCIÓN | E35: BANCO | G35: TOTAL EFECTIVO MENOS LA BASE: | I35: =I33-I34 -> 0
A36: =IF(B36="","",VLOOKUP(B36,PROVEEDORES!$B:$C,2,FALSE)) | E36: 0
A37: =IF(B37="","",VLOOKUP(B37,PROVEEDORES!$B:$C,2,FALSE)) | E37: 0 | G37: ACUM. DE PROPINA TRANSFERENCIA: | I37: 0
A38: =IF(B38="","",VLOOKUP(B38,PROVEEDORES!$B:$C,2,FALSE)) | E38: 0 | G38: ACUMULADO DE PROPINA EN BANCO: | I38: 0
A39: =IF(B39="","",VLOOKUP(B39,PROVEEDORES!$B:$C,2,FALSE)) | E39: 0 | G39: ACUMULADO DE PROPINA POR EFECTIVO: | I39: 0
A40: =IF(B40="","",VLOOKUP(B40,PROVEEDORES!$B:$C,2,FALSE)) | E40: 0 | G40: ACUMULADO DE TRANSFERENCIA: | I40: 0
...

Sheet 2
A1: ='1'!A1+1 -> 2 | B1: =+'1'!B1 -> QUESO Y CAFÉ | D1: =+'1'!D1:E1+1 -> 46144 | G1: CUADRE DE CAJA MAÑANA | I1: CUADRE DE CAJA TARDE
A2: NIT | B2: PROVEEDOR | C2: CONCEPTO | D2: DESCRIPCIÓN | E2: VALOR | G2: PROP. TRANSF.: | H2: 0 | I2: PROP. TRANSF.: | J2: 0
A3: =IF(B3="","",VLOOKUP(B3,PROVEEDORES!$B:$C,2,FALSE)) | E3: 0 | G3: PROP. BANCO: | H3: 0 | I3: PROP. BANCO: | J3: 0
A4: =IF(B4="","",VLOOKUP(B4,PROVEEDORES!$B:$C,2,FALSE)) | E4: 0 | G4: PROP. EFECTIVO: | H4: 0 | I4: PROP. EFECTIVO: | J4: 0
A5: =IF(B5="","",VLOOKUP(B5,PROVEEDORES!$B:$C,2,FALSE)) | E5: 0 | G5: GASTO: | H5: 0 | I5: GASTO: | J5: 0
A6: =IF(B6="","",VLOOKUP(B6,PROVEEDORES!$B:$C,2,FALSE)) | E6: 0 | G6: TRANSFERENCIA: | H6: 0 | I6: TRANSFERENCIA: | J6: 0
A7: =IF(B7="","",VLOOKUP(B7,PROVEEDORES!$B:$C,2,FALSE)) | E7: 0 | G7: BANCO: | H7: 0 | I7: BANCO: | J7: 0
A8: =IF(B8="","",VLOOKUP(B8,PROVEEDORES!$B:$C,2,FALSE)) | E8: 0 | G8: EFECTIVO: | H8: 0 | I8: EFECTIVO: | J8: 0
A9: =IF(B9="","",VLOOKUP(B9,PROVEEDORES!$B:$C,2,FALSE)) | E9: 0 | G9: TOTAL: | H9: =SUM(H5:H8) -> 0 | I9: TOTAL: | J9: =SUM(J5:J8) -> 0
A10: =IF(B10="","",VLOOKUP(B10,PROVEEDORES!$B:$C,2,FALSE)) | E10: 0 | G10: DIFERENCIA: | H10: =+H11-H9 -> 0 | I10: DIFERENCIA: | J10: =+J11-J9 -> 0
A11: =IF(B11="","",VLOOKUP(B11,PROVEEDORES!$B:$C,2,FALSE)) | E11: 0 | G11: TOTAL VENTA: | H11: 0 | I11: TOTAL VENTA: | J11: 0
A12: =IF(B12="","",VLOOKUP(B12,PROVEEDORES!$B:$C,2,FALSE)) | E12: 0
A13: PROPINA TRANSFERENCIA: | C13: =SUM(H2,J2) -> 0 | D13: ACUM. PROPINA TRANFERENCIA: | E13: =SUM(C13,I37)-C57 -> 0 | G13: DIFERENCIA PLANILLA VS CUADRE DE CAJA | I13: =+C20-(SUM(H9,J9)) -> 0
A14: PROPINA POR BANCO: | C14: =SUM(H3,J3) -> 0 | D14: ACUM. PROPINA BANCO: | E14: =SUM(C14,I38)-C58 -> 0
A15: PROPINA EN EFECTIVO: | C15: =SUM(H4,J4) -> 0 | D15: ACUM. PROPINA EFECTIVO: | E15: =SUM(C15,I39)-C59 -> 0 | G15: FACTURAS EN EFECTIVO: | I15: 0
A16: TOTAL EGRESOS: | C16: =SUM(E3:E12) -> 0 | D16: ACUMULADO TRANSFERENCIA: | E16: =SUM(C17,I40) -> 0 | G16: EFECTIVO: | I16: 0
A17: TRANSFERENCIA: | C17: =SUM(H6,J6) -> 0 | D17: ACUMULADO BANCO: | E17: =SUM(C18,I41) -> 0 | G17: TOTAL EFECTIVO REAL ACTUAL: | I17: =SUM(I15,I16) -> 0
A18: BANCO: | C18: =SUM(H7,J7) -> 0 | D18: TOTAL BANCO: | E18: =SUM(C18,I42)-(SUM(E36:E55)) -> 0 | G18: DIFERENCIA: | I18: =+I19-I17 -> 0
A19: EFECTIVO: | C19: =SUM(H8,J8) -> 0 | D19: TOTAL EFECTIVO: | E19: =SUM(C19,E20,E57:E59)-(SUM(E23:E34)) -> 0 | G19: EFECTIVO ACTUAL PLANILLA: | I19: =E19 -> 0
A20: TOTAL VENTA: | C20: =SUM(C16:C19) -> 0 | D20: EFECTIVO ANTERIOR: | E20: =+I43 -> 0
A21: EGRESO DE CAJA MAYOR | G21: CONTEO DE EFECTIVO
A22: NIT | B22: PROVEEDOR | C22: CONCEPTO | D22: DESCRIPCIÓN | E22: EFECTIVO | G22: DENOMINACIÓN | H22: CANTIDAD | I22: EFECTIVO
A23: =IF(B23="","",VLOOKUP(B23,PROVEEDORES!$B:$C,2,FALSE)) | E23: 0 | G23: MONEDAS DE 100 | H23: 0 | I23: =100*H23 -> 0
A24: =IF(B24="","",VLOOKUP(B24,PROVEEDORES!$B:$C,2,FALSE)) | E24: 0 | G24: MONEDAS DE 200 | H24: 0 | I24: =200*H24 -> 0
A25: =IF(B25="","",VLOOKUP(B25,PROVEEDORES!$B:$C,2,FALSE)) | E25: 0 | G25: MONEDAS DE 500 | H25: 0 | I25: =500*H25 -> 0
A26: =IF(B26="","",VLOOKUP(B26,PROVEEDORES!$B:$C,2,FALSE)) | E26: 0 | G26: MONEDAS DE 1.000 | H26: 0 | I26: =1000*H26 -> 0
A27: =IF(B27="","",VLOOKUP(B27,PROVEEDORES!$B:$C,2,FALSE)) | E27: 0 | G27: BILLETES DE 2.000 | H27: 0 | I27: =2000*H27 -> 0
A28: =IF(B28="","",VLOOKUP(B28,PROVEEDORES!$B:$C,2,FALSE)) | E28: 0 | G28: BILLETES DE 5.000 | H28: 0 | I28: =5000*H28 -> 0
A29: =IF(B29="","",VLOOKUP(B29,PROVEEDORES!$B:$C,2,FALSE)) | E29: 0 | G29: BILLETES DE 10.000 | H29: 0 | I29: =10000*H29 -> 0
A30: =IF(B30="","",VLOOKUP(B30,PROVEEDORES!$B:$C,2,FALSE)) | E30: 0 | G30: BILLETES DE 20.000 | H30: 0 | I30: =20000*H30 -> 0
A31: =IF(B31="","",VLOOKUP(B31,PROVEEDORES!$B:$C,2,FALSE)) | E31: 0 | G31: BILLETES DE 50.000 | H31: 0 | I31: =50000*H31 -> 0
A32: =IF(B32="","",VLOOKUP(B32,PROVEEDORES!$B:$C,2,FALSE)) | E32: 0 | G32: BILLETES DE 100.000 | H32: 0 | I32: =100000*H32 -> 0
A33: =IF(B33="","",VLOOKUP(B33,PROVEEDORES!$B:$C,2,FALSE)) | E33: 0 | G33: TOTAL EFECTIVO: | I33: =SUM(I23:I32) -> 0
A34: =IF(B34="","",VLOOKUP(B34,PROVEEDORES!$B:$C,2,FALSE)) | E34: 0 | G34: BASE: | I34: 0
A35: NIT | B35: PROVEEDOR | C35: CONCEPTO | D35: DESCRIPCIÓN | E35: BANCO | G35: TOTAL EFECTIVO MENOS LA BASE: | I35: =I33-I34 -> 0
A36: =IF(B36="","",VLOOKUP(B36,PROVEEDORES!$B:$C,2,FALSE)) | E36: 0
A37: =IF(B37="","",VLOOKUP(B37,PROVEEDORES!$B:$C,2,FALSE)) | E37: 0 | G37: ACUM. DE PROPINA TRANSFERENCIA: | I37: =+'1'!E13 -> 0
A38: =IF(B38="","",VLOOKUP(B38,PROVEEDORES!$B:$C,2,FALSE)) | E38: 0 | G38: ACUMULADO DE PROPINA EN BANCO: | I38: =+'1'!E14 -> 0
A39: =IF(B39="","",VLOOKUP(B39,PROVEEDORES!$B:$C,2,FALSE)) | E39: 0 | G39: ACUMULADO DE PROPINA POR EFECTIVO: | I39: =+'1'!E15 -> 0
A40: =IF(B40="","",VLOOKUP(B40,PROVEEDORES!$B:$C,2,FALSE)) | E40: 0 | G40: ACUMULADO DE TRANSFERENCIA: | I40: =+'1'!E16 -> 0
...

Sheet 3
A1: ='2'!A1+1 -> 3 | B1: =+'1'!B1 -> QUESO Y CAFÉ | D1: =+'2'!D1:E1+1 -> 46145 | G1: CUADRE DE CAJA MAÑANA | I1: CUADRE DE CAJA TARDE
A2: NIT | B2: PROVEEDOR | C2: CONCEPTO | D2: DESCRIPCIÓN | E2: VALOR | G2: PROP. TRANSF.: | H2: 0 | I2: PROP. TRANSF.: | J2: 0
A3: =IF(B3="","",VLOOKUP(B3,PROVEEDORES!$B:$C,2,FALSE)) | E3: 0 | G3: PROP. BANCO: | H3: 0 | I3: PROP. BANCO: | J3: 0
A4: =IF(B4="","",VLOOKUP(B4,PROVEEDORES!$B:$C,2,FALSE)) | E4: 0 | G4: PROP. EFECTIVO: | H4: 0 | I4: PROP. EFECTIVO: | J4: 0
A5: =IF(B5="","",VLOOKUP(B5,PROVEEDORES!$B:$C,2,FALSE)) | E5: 0 | G5: GASTO: | H5: 0 | I5: GASTO: | J5: 0
A6: =IF(B6="","",VLOOKUP(B6,PROVEEDORES!$B:$C,2,FALSE)) | E6: 0 | G6: TRANSFERENCIA: | H6: 0 | I6: TRANSFERENCIA: | J6: 0
A7: =IF(B7="","",VLOOKUP(B7,PROVEEDORES!$B:$C,2,FALSE)) | E7: 0 | G7: BANCO: | H7: 0 | I7: BANCO: | J7: 0
A8: =IF(B8="","",VLOOKUP(B8,PROVEEDORES!$B:$C,2,FALSE)) | E8: 0 | G8: EFECTIVO: | H8: 0 | I8: EFECTIVO: | J8: 0
A9: =IF(B9="","",VLOOKUP(B9,PROVEEDORES!$B:$C,2,FALSE)) | E9: 0 | G9: TOTAL: | H9: =SUM(H5:H8) -> 0 | I9: TOTAL: | J9: =SUM(J5:J8) -> 0
A10: =IF(B10="","",VLOOKUP(B10,PROVEEDORES!$B:$C,2,FALSE)) | E10: 0 | G10: DIFERENCIA: | H10: =+H11-H9 -> 0 | I10: DIFERENCIA: | J10: =+J11-J9 -> 0
A11: =IF(B11="","",VLOOKUP(B11,PROVEEDORES!$B:$C,2,FALSE)) | E11: 0 | G11: TOTAL VENTA: | H11: 0 | I11: TOTAL VENTA: | J11: 0
A12: =IF(B12="","",VLOOKUP(B12,PROVEEDORES!$B:$C,2,FALSE)) | E12: 0
A13: PROPINA TRANSFERENCIA: | C13: =SUM(H2,J2) -> 0 | D13: ACUM. PROPINA TRANFERENCIA: | E13: =SUM(C13,I37)-C57 -> 0 | G13: DIFERENCIA PLANILLA VS CUADRE DE CAJA | I13: =+C20-(SUM(H9,J9)) -> 0
A14: PROPINA POR BANCO: | C14: =SUM(H3,J3) -> 0 | D14: ACUM. PROPINA BANCO: | E14: =SUM(C14,I38)-C58 -> 0
A15: PROPINA EN EFECTIVO: | C15: =SUM(H4,J4) -> 0 | D15: ACUM. PROPINA EFECTIVO: | E15: =SUM(C15,I39)-C59 -> 0 | G15: FACTURAS EN EFECTIVO: | I15: 0
A16: TOTAL EGRESOS: | C16: =SUM(E3:E12) -> 0 | D16: ACUMULADO TRANSFERENCIA: | E16: =SUM(C17,I40) -> 0 | G16: EFECTIVO: | I16: 0
A17: TRANSFERENCIA: | C17: =SUM(H6,J6) -> 0 | D17: ACUMULADO BANCO: | E17: =SUM(C18,I41) -> 0 | G17: TOTAL EFECTIVO REAL ACTUAL: | I17: =SUM(I15,I16) -> 0
A18: BANCO: | C18: =SUM(H7,J7) -> 0 | D18: TOTAL BANCO: | E18: =SUM(C18,I42)-(SUM(E36:E55)) -> 0 | G18: DIFERENCIA: | I18: =+I19-I17 -> 0
A19: EFECTIVO: | C19: =SUM(H8,J8) -> 0 | D19: TOTAL EFECTIVO: | E19: =SUM(C19,E20,E57:E59)-(SUM(E23:E34)) -> 0 | G19: EFECTIVO ACTUAL PLANILLA: | I19: =E19 -> 0
A20: TOTAL VENTA: | C20: =SUM(C16:C19) -> 0 | D20: EFECTIVO ANTERIOR: | E20: =+I43 -> 0
A21: EGRESO DE CAJA MAYOR | G21: CONTEO DE EFECTIVO
A22: NIT | B22: PROVEEDOR | C22: CONCEPTO | D22: DESCRIPCIÓN | E22: EFECTIVO | G22: DENOMINACIÓN | H22: CANTIDAD | I22: EFECTIVO
A23: =IF(B23="","",VLOOKUP(B23,PROVEEDORES!$B:$C,2,FALSE)) | E23: 0 | G23: MONEDAS DE 100 | H23: 0 | I23: =100*H23 -> 0
A24: =IF(B24="","",VLOOKUP(B24,PROVEEDORES!$B:$C,2,FALSE)) | E24: 0 | G24: MONEDAS DE 200 | H24: 0 | I24: =200*H24 -> 0
A25: =IF(B25="","",VLOOKUP(B25,PROVEEDORES!$B:$C,2,FALSE)) | E25: 0 | G25: MONEDAS DE 500 | H25: 0 | I25: =500*H25 -> 0
A26: =IF(B26="","",VLOOKUP(B26,PROVEEDORES!$B:$C,2,FALSE)) | E26: 0 | G26: MONEDAS DE 1.000 | H26: 0 | I26: =1000*H26 -> 0
A27: =IF(B27="","",VLOOKUP(B27,PROVEEDORES!$B:$C,2,FALSE)) | E27: 0 | G27: BILLETES DE 2.000 | H27: 0 | I27: =2000*H27 -> 0
A28: =IF(B28="","",VLOOKUP(B28,PROVEEDORES!$B:$C,2,FALSE)) | E28: 0 | G28: BILLETES DE 5.000 | H28: 0 | I28: =5000*H28 -> 0
A29: =IF(B29="","",VLOOKUP(B29,PROVEEDORES!$B:$C,2,FALSE)) | E29: 0 | G29: BILLETES DE 10.000 | H29: 0 | I29: =10000*H29 -> 0
A30: =IF(B30="","",VLOOKUP(B30,PROVEEDORES!$B:$C,2,FALSE)) | E30: 0 | G30: BILLETES DE 20.000 | H30: 0 | I30: =20000*H30 -> 0
A31: =IF(B31="","",VLOOKUP(B31,PROVEEDORES!$B:$C,2,FALSE)) | E31: 0 | G31: BILLETES DE 50.000 | H31: 0 | I31: =50000*H31 -> 0
A32: =IF(B32="","",VLOOKUP(B32,PROVEEDORES!$B:$C,2,FALSE)) | E32: 0 | G32: BILLETES DE 100.000 | H32: 0 | I32: =100000*H32 -> 0
A33: =IF(B33="","",VLOOKUP(B33,PROVEEDORES!$B:$C,2,FALSE)) | E33: 0 | G33: TOTAL EFECTIVO: | I33: =SUM(I23:I32) -> 0
A34: =IF(B34="","",VLOOKUP(B34,PROVEEDORES!$B:$C,2,FALSE)) | E34: 0 | G34: BASE: | I34: 0
A35: NIT | B35: PROVEEDOR | C35: CONCEPTO | D35: DESCRIPCIÓN | E35: BANCO | G35: TOTAL EFECTIVO MENOS LA BASE: | I35: =I33-I34 -> 0
A36: =IF(B36="","",VLOOKUP(B36,PROVEEDORES!$B:$C,2,FALSE)) | E36: 0
A37: =IF(B37="","",VLOOKUP(B37,PROVEEDORES!$B:$C,2,FALSE)) | E37: 0 | G37: ACUM. DE PROPINA TRANSFERENCIA: | I37: =+'2'!E13 -> 0
A38: =IF(B38="","",VLOOKUP(B38,PROVEEDORES!$B:$C,2,FALSE)) | E38: 0 | G38: ACUMULADO DE PROPINA EN BANCO: | I38: =+'2'!E14 -> 0
A39: =IF(B39="","",VLOOKUP(B39,PROVEEDORES!$B:$C,2,FALSE)) | E39: 0 | G39: ACUMULADO DE PROPINA POR EFECTIVO: | I39: =+'2'!E15 -> 0
A40: =IF(B40="","",VLOOKUP(B40,PROVEEDORES!$B:$C,2,FALSE)) | E40: 0 | G40: ACUMULADO DE TRANSFERENCIA: | I40: =+'2'!E16 -> 0
...

Sheet 4
A1: ='3'!A1+1 -> 4 | B1: =+'1'!B1 -> QUESO Y CAFÉ | D1: =+'3'!D1:E1+1 -> 46146 | G1: CUADRE DE CAJA MAÑANA | I1: CUADRE DE CAJA TARDE
A2: NIT | B2: PROVEEDOR | C2: CONCEPTO | D2: DESCRIPCIÓN | E2: VALOR | G2: PROP. TRANSF.: | H2: 0 | I2: PROP. TRANSF.: | J2: 0
A3: =IF(B3="","",VLOOKUP(B3,PROVEEDORES!$B:$C,2,FALSE)) | E3: 0 | G3: PROP. BANCO: | H3: 0 | I3: PROP. BANCO: | J3: 0
A4: =IF(B4="","",VLOOKUP(B4,PROVEEDORES!$B:$C,2,FALSE)) | E4: 0 | G4: PROP. EFECTIVO: | H4: 0 | I4: PROP. EFECTIVO: | J4: 0
A5: =IF(B5="","",VLOOKUP(B5,PROVEEDORES!$B:$C,2,FALSE)) | E5: 0 | G5: GASTO: | H5: 0 | I5: GASTO: | J5: 0
A6: =IF(B6="","",VLOOKUP(B6,PROVEEDORES!$B:$C,2,FALSE)) | E6: 0 | G6: TRANSFERENCIA: | H6: 0 | I6: TRANSFERENCIA: | J6: 0
A7: =IF(B7="","",VLOOKUP(B7,PROVEEDORES!$B:$C,2,FALSE)) | E7: 0 | G7: BANCO: | H7: 0 | I7: BANCO: | J7: 0
A8: =IF(B8="","",VLOOKUP(B8,PROVEEDORES!$B:$C,2,FALSE)) | E8: 0 | G8: EFECTIVO: | H8: 0 | I8: EFECTIVO: | J8: 0
A9: =IF(B9="","",VLOOKUP(B9,PROVEEDORES!$B:$C,2,FALSE)) | E9: 0 | G9: TOTAL: | H9: =SUM(H5:H8) -> 0 | I9: TOTAL: | J9: =SUM(J5:J8) -> 0
A10: =IF(B10="","",VLOOKUP(B10,PROVEEDORES!$B:$C,2,FALSE)) | E10: 0 | G10: DIFERENCIA: | H10: =+H11-H9 -> 0 | I10: DIFERENCIA: | J10: =+J11-J9 -> 0
A11: =IF(B11="","",VLOOKUP(B11,PROVEEDORES!$B:$C,2,FALSE)) | E11: 0 | G11: TOTAL VENTA: | H11: 0 | I11: TOTAL VENTA: | J11: 0
A12: =IF(B12="","",VLOOKUP(B12,PROVEEDORES!$B:$C,2,FALSE)) | E12: 0
A13: PROPINA TRANSFERENCIA: | C13: =SUM(H2,J2) -> 0 | D13: ACUM. PROPINA TRANFERENCIA: | E13: =SUM(C13,I37)-C57 -> 0 | G13: DIFERENCIA PLANILLA VS CUADRE DE CAJA | I13: =+C20-(SUM(H9,J9)) -> 0
A14: PROPINA POR BANCO: | C14: =SUM(H3,J3) -> 0 | D14: ACUM. PROPINA BANCO: | E14: =SUM(C14,I38)-C58 -> 0
A15: PROPINA EN EFECTIVO: | C15: =SUM(H4,J4) -> 0 | D15: ACUM. PROPINA EFECTIVO: | E15: =SUM(C15,I39)-C59 -> 0 | G15: FACTURAS EN EFECTIVO: | I15: 0
A16: TOTAL EGRESOS: | C16: =SUM(E3:E12) -> 0 | D16: ACUMULADO TRANSFERENCIA: | E16: =SUM(C17,I40) -> 0 | G16: EFECTIVO: | I16: 0
A17: TRANSFERENCIA: | C17: =SUM(H6,J6) -> 0 | D17: ACUMULADO BANCO: | E17: =SUM(C18,I41) -> 0 | G17: TOTAL EFECTIVO REAL ACTUAL: | I17: =SUM(I15,I16) -> 0
A18: BANCO: | C18: =SUM(H7,J7) -> 0 | D18: TOTAL BANCO: | E18: =SUM(C18,I42)-(SUM(E36:E55)) -> 0 | G18: DIFERENCIA: | I18: =+I19-I17 -> 0
A19: EFECTIVO: | C19: =SUM(H8,J8) -> 0 | D19: TOTAL EFECTIVO: | E19: =SUM(C19,E20,E57:E59)-(SUM(E23:E34)) -> 0 | G19: EFECTIVO ACTUAL PLANILLA: | I19: =E19 -> 0
A20: TOTAL VENTA: | C20: =SUM(C16:C19) -> 0 | D20: EFECTIVO ANTERIOR: | E20: =+I43 -> 0
A21: EGRESO DE CAJA MAYOR | G21: CONTEO DE EFECTIVO
A22: NIT | B22: PROVEEDOR | C22: CONCEPTO | D22: DESCRIPCIÓN | E22: EFECTIVO | G22: DENOMINACIÓN | H22: CANTIDAD | I22: EFECTIVO
A23: =IF(B23="","",VLOOKUP(B23,PROVEEDORES!$B:$C,2,FALSE)) | E23: 0 | G23: MONEDAS DE 100 | H23: 0 | I23: =100*H23 -> 0
A24: =IF(B24="","",VLOOKUP(B24,PROVEEDORES!$B:$C,2,FALSE)) | E24: 0 | G24: MONEDAS DE 200 | H24: 0 | I24: =200*H24 -> 0
A25: =IF(B25="","",VLOOKUP(B25,PROVEEDORES!$B:$C,2,FALSE)) | E25: 0 | G25: MONEDAS DE 500 | H25: 0 | I25: =500*H25 -> 0
A26: =IF(B26="","",VLOOKUP(B26,PROVEEDORES!$B:$C,2,FALSE)) | E26: 0 | G26: MONEDAS DE 1.000 | H26: 0 | I26: =1000*H26 -> 0
A27: =IF(B27="","",VLOOKUP(B27,PROVEEDORES!$B:$C,2,FALSE)) | E27: 0 | G27: BILLETES DE 2.000 | H27: 0 | I27: =2000*H27 -> 0
A28: =IF(B28="","",VLOOKUP(B28,PROVEEDORES!$B:$C,2,FALSE)) | E28: 0 | G28: BILLETES DE 5.000 | H28: 0 | I28: =5000*H28 -> 0
A29: =IF(B29="","",VLOOKUP(B29,PROVEEDORES!$B:$C,2,FALSE)) | E29: 0 | G29: BILLETES DE 10.000 | H29: 0 | I29: =10000*H29 -> 0
A30: =IF(B30="","",VLOOKUP(B30,PROVEEDORES!$B:$C,2,FALSE)) | E30: 0 | G30: BILLETES DE 20.000 | H30: 0 | I30: =20000*H30 -> 0
A31: =IF(B31="","",VLOOKUP(B31,PROVEEDORES!$B:$C,2,FALSE)) | E31: 0 | G31: BILLETES DE 50.000 | H31: 0 | I31: =50000*H31 -> 0
A32: =IF(B32="","",VLOOKUP(B32,PROVEEDORES!$B:$C,2,FALSE)) | E32: 0 | G32: BILLETES DE 100.000 | H32: 0 | I32: =100000*H32 -> 0
A33: =IF(B33="","",VLOOKUP(B33,PROVEEDORES!$B:$C,2,FALSE)) | E33: 0 | G33: TOTAL EFECTIVO: | I33: =SUM(I23:I32) -> 0
A34: =IF(B34="","",VLOOKUP(B34,PROVEEDORES!$B:$C,2,FALSE)) | E34: 0 | G34: BASE: | I34: 0
A35: NIT | B35: PROVEEDOR | C35: CONCEPTO | D35: DESCRIPCIÓN | E35: BANCO | G35: TOTAL EFECTIVO MENOS LA BASE: | I35: =I33-I34 -> 0
A36: =IF(B36="","",VLOOKUP(B36,PROVEEDORES!$B:$C,2,FALSE)) | E36: 0
A37: =IF(B37="","",VLOOKUP(B37,PROVEEDORES!$B:$C,2,FALSE)) | E37: 0 | G37: ACUM. DE PROPINA TRANSFERENCIA: | I37: =+'3'!E13 -> 0
A38: =IF(B38="","",VLOOKUP(B38,PROVEEDORES!$B:$C,2,FALSE)) | E38: 0 | G38: ACUMULADO DE PROPINA EN BANCO: | I38: =+'3'!E14 -> 0
A39: =IF(B39="","",VLOOKUP(B39,PROVEEDORES!$B:$C,2,FALSE)) | E39: 0 | G39: ACUMULADO DE PROPINA POR EFECTIVO: | I39: =+'3'!E15 -> 0
A40: =IF(B40="","",VLOOKUP(B40,PROVEEDORES!$B:$C,2,FALSE)) | E40: 0 | G40: ACUMULADO DE TRANSFERENCIA: | I40: =+'3'!E16 -> 0
...

Sheet 5
A1: ='4'!A1+1 -> 5 | B1: =+'1'!B1 -> QUESO Y CAFÉ | D1: =+'4'!D1:E1+1 -> 46147 | G1: CUADRE DE CAJA MAÑANA | I1: CUADRE DE CAJA TARDE
A2: NIT | B2: PROVEEDOR | C2: CONCEPTO | D2: DESCRIPCIÓN | E2: VALOR | G2: PROP. TRANSF.: | H2: 0 | I2: PROP. TRANSF.: | J2: 0
A3: =IF(B3="","",VLOOKUP(B3,PROVEEDORES!$B:$C,2,FALSE)) | E3: 0 | G3: PROP. BANCO: | H3: 0 | I3: PROP. BANCO: | J3: 0
A4: =IF(B4="","",VLOOKUP(B4,PROVEEDORES!$B:$C,2,FALSE)) | E4: 0 | G4: PROP. EFECTIVO: | H4: 0 | I4: PROP. EFECTIVO: | J4: 0
A5: =IF(B5="","",VLOOKUP(B5,PROVEEDORES!$B:$C,2,FALSE)) | E5: 0 | G5: GASTO: | H5: 0 | I5: GASTO: | J5: 0
A6: =IF(B6="","",VLOOKUP(B6,PROVEEDORES!$B:$C,2,FALSE)) | E6: 0 | G6: TRANSFERENCIA: | H6: 0 | I6: TRANSFERENCIA: | J6: 0
A7: =IF(B7="","",VLOOKUP(B7,PROVEEDORES!$B:$C,2,FALSE)) | E7: 0 | G7: BANCO: | H7: 0 | I7: BANCO: | J7: 0
A8: =IF(B8="","",VLOOKUP(B8,PROVEEDORES!$B:$C,2,FALSE)) | E8: 0 | G8: EFECTIVO: | H8: 0 | I8: EFECTIVO: | J8: 0
A9: =IF(B9="","",VLOOKUP(B9,PROVEEDORES!$B:$C,2,FALSE)) | E9: 0 | G9: TOTAL: | H9: =SUM(H5:H8) -> 0 | I9: TOTAL: | J9: =SUM(J5:J8) -> 0
A10: =IF(B10="","",VLOOKUP(B10,PROVEEDORES!$B:$C,2,FALSE)) | E10: 0 | G10: DIFERENCIA: | H10: =+H11-H9 -> 0 | I10: DIFERENCIA: | J10: =+J11-J9 -> 0
A11: =IF(B11="","",VLOOKUP(B11,PROVEEDORES!$B:$C,2,FALSE)) | E11: 0 | G11: TOTAL VENTA: | H11: 0 | I11: TOTAL VENTA: | J11: 0
A12: =IF(B12="","",VLOOKUP(B12,PROVEEDORES!$B:$C,2,FALSE)) | E12: 0
A13: PROPINA TRANSFERENCIA: | C13: =SUM(H2,J2) -> 0 | D13: ACUM. PROPINA TRANFERENCIA: | E13: =SUM(C13,I37)-C57 -> 0 | G13: DIFERENCIA PLANILLA VS CUADRE DE CAJA | I13: =+C20-(SUM(H9,J9)) -> 0
A14: PROPINA POR BANCO: | C14: =SUM(H3,J3) -> 0 | D14: ACUM. PROPINA BANCO: | E14: =SUM(C14,I38)-C58 -> 0
A15: PROPINA EN EFECTIVO: | C15: =SUM(H4,J4) -> 0 | D15: ACUM. PROPINA EFECTIVO: | E15: =SUM(C15,I39)-C59 -> 0 | G15: FACTURAS EN EFECTIVO: | I15: 0
A16: TOTAL EGRESOS: | C16: =SUM(E3:E12) -> 0 | D16: ACUMULADO TRANSFERENCIA: | E16: =SUM(C17,I40) -> 0 | G16: EFECTIVO: | I16: 0
A17: TRANSFERENCIA: | C17: =SUM(H6,J6) -> 0 | D17: ACUMULADO BANCO: | E17: =SUM(C18,I41) -> 0 | G17: TOTAL EFECTIVO REAL ACTUAL: | I17: =SUM(I15,I16) -> 0
A18: BANCO: | C18: =SUM(H7,J7) -> 0 | D18: TOTAL BANCO: | E18: =SUM(C18,I42)-(SUM(E36:E55)) -> 0 | G18: DIFERENCIA: | I18: =+I19-I17 -> 0
A19: EFECTIVO: | C19: =SUM(H8,J8) -> 0 | D19: TOTAL EFECTIVO: | E19: =SUM(C19,E20,E57:E59)-(SUM(E23:E34)) -> 0 | G19: EFECTIVO ACTUAL PLANILLA: | I19: =E19 -> 0
A20: TOTAL VENTA: | C20: =SUM(C16:C19) -> 0 | D20: EFECTIVO ANTERIOR: | E20: =+I43 -> 0
A21: EGRESO DE CAJA MAYOR | G21: CONTEO DE EFECTIVO
A22: NIT | B22: PROVEEDOR | C22: CONCEPTO | D22: DESCRIPCIÓN | E22: EFECTIVO | G22: DENOMINACIÓN | H22: CANTIDAD | I22: EFECTIVO
A23: =IF(B23="","",VLOOKUP(B23,PROVEEDORES!$B:$C,2,FALSE)) | E23: 0 | G23: MONEDAS DE 100 | H23: 0 | I23: =100*H23 -> 0
A24: =IF(B24="","",VLOOKUP(B24,PROVEEDORES!$B:$C,2,FALSE)) | E24: 0 | G24: MONEDAS DE 200 | H24: 0 | I24: =200*H24 -> 0
A25: =IF(B25="","",VLOOKUP(B25,PROVEEDORES!$B:$C,2,FALSE)) | E25: 0 | G25: MONEDAS DE 500 | H25: 0 | I25: =500*H25 -> 0
A26: =IF(B26="","",VLOOKUP(B26,PROVEEDORES!$B:$C,2,FALSE)) | E26: 0 | G26: MONEDAS DE 1.000 | H26: 0 | I26: =1000*H26 -> 0
A27: =IF(B27="","",VLOOKUP(B27,PROVEEDORES!$B:$C,2,FALSE)) | E27: 0 | G27: BILLETES DE 2.000 | H27: 0 | I27: =2000*H27 -> 0
A28: =IF(B28="","",VLOOKUP(B28,PROVEEDORES!$B:$C,2,FALSE)) | E28: 0 | G28: BILLETES DE 5.000 | H28: 0 | I28: =5000*H28 -> 0
A29: =IF(B29="","",VLOOKUP(B29,PROVEEDORES!$B:$C,2,FALSE)) | E29: 0 | G29: BILLETES DE 10.000 | H29: 0 | I29: =10000*H29 -> 0
A30: =IF(B30="","",VLOOKUP(B30,PROVEEDORES!$B:$C,2,FALSE)) | E30: 0 | G30: BILLETES DE 20.000 | H30: 0 | I30: =20000*H30 -> 0
A31: =IF(B31="","",VLOOKUP(B31,PROVEEDORES!$B:$C,2,FALSE)) | E31: 0 | G31: BILLETES DE 50.000 | H31: 0 | I31: =50000*H31 -> 0
A32: =IF(B32="","",VLOOKUP(B32,PROVEEDORES!$B:$C,2,FALSE)) | E32: 0 | G32: BILLETES DE 100.000 | H32: 0 | I32: =100000*H32 -> 0
A33: =IF(B33="","",VLOOKUP(B33,PROVEEDORES!$B:$C,2,FALSE)) | E33: 0 | G33: TOTAL EFECTIVO: | I33: =SUM(I23:I32) -> 0
A34: =IF(B34="","",VLOOKUP(B34,PROVEEDORES!$B:$C,2,FALSE)) | E34: 0 | G34: BASE: | I34: 0
A35: NIT | B35: PROVEEDOR | C35: CONCEPTO | D35: DESCRIPCIÓN | E35: BANCO | G35: TOTAL EFECTIVO MENOS LA BASE: | I35: =I33-I34 -> 0
A36: =IF(B36="","",VLOOKUP(B36,PROVEEDORES!$B:$C,2,FALSE)) | E36: 0
A37: =IF(B37="","",VLOOKUP(B37,PROVEEDORES!$B:$C,2,FALSE)) | E37: 0 | G37: ACUM. DE PROPINA TRANSFERENCIA: | I37: =+'4'!E13 -> 0
A38: =IF(B38="","",VLOOKUP(B38,PROVEEDORES!$B:$C,2,FALSE)) | E38: 0 | G38: ACUMULADO DE PROPINA EN BANCO: | I38: =+'4'!E14 -> 0
A39: =IF(B39="","",VLOOKUP(B39,PROVEEDORES!$B:$C,2,FALSE)) | E39: 0 | G39: ACUMULADO DE PROPINA POR EFECTIVO: | I39: =+'4'!E15 -> 0
A40: =IF(B40="","",VLOOKUP(B40,PROVEEDORES!$B:$C,2,FALSE)) | E40: 0 | G40: ACUMULADO DE TRANSFERENCIA: | I40: =+'4'!E16 -> 0
...

Sheet 6
A1: ='5'!A1+1 -> 6 | B1: =+'1'!B1 -> QUESO Y CAFÉ | D1: =+'5'!D1:E1+1 -> 46148 | G1: CUADRE DE CAJA MAÑANA | I1: CUADRE DE CAJA TARDE
A2: NIT | B2: PROVEEDOR | C2: CONCEPTO | D2: DESCRIPCIÓN | E2: VALOR | G2: PROP. TRANSF.: | H2: 0 | I2: PROP. TRANSF.: | J2: 0
A3: =IF(B3="","",VLOOKUP(B3,PROVEEDORES!$B:$C,2,FALSE)) | E3: 0 | G3: PROP. BANCO: | H3: 0 | I3: PROP. BANCO: | J3: 0
A4: =IF(B4="","",VLOOKUP(B4,PROVEEDORES!$B:$C,2,FALSE)) | E4: 0 | G4: PROP. EFECTIVO: | H4: 0 | I4: PROP. EFECTIVO: | J4: 0
A5: =IF(B5="","",VLOOKUP(B5,PROVEEDORES!$B:$C,2,FALSE)) | E5: 0 | G5: GASTO: | H5: 0 | I5: GASTO: | J5: 0
A6: =IF(B6="","",VLOOKUP(B6,PROVEEDORES!$B:$C,2,FALSE)) | E6: 0 | G6: TRANSFERENCIA: | H6: 0 | I6: TRANSFERENCIA: | J6: 0
A7: =IF(B7="","",VLOOKUP(B7,PROVEEDORES!$B:$C,2,FALSE)) | E7: 0 | G7: BANCO: | H7: 0 | I7: BANCO: | J7: 0
A8: =IF(B8="","",VLOOKUP(B8,PROVEEDORES!$B:$C,2,FALSE)) | E8: 0 | G8: EFECTIVO: | H8: 0 | I8: EFECTIVO: | J8: 0
A9: =IF(B9="","",VLOOKUP(B9,PROVEEDORES!$B:$C,2,FALSE)) | E9: 0 | G9: TOTAL: | H9: =SUM(H5:H8) -> 0 | I9: TOTAL: | J9: =SUM(J5:J8) -> 0
A10: =IF(B10="","",VLOOKUP(B10,PROVEEDORES!$B:$C,2,FALSE)) | E10: 0 | G10: DIFERENCIA: | H10: =+H11-H9 -> 0 | I10: DIFERENCIA: | J10: =+J11-J9 -> 0
A11: =IF(B11="","",VLOOKUP(B11,PROVEEDORES!$B:$C,2,FALSE)) | E11: 0 | G11: TOTAL VENTA: | H11: 0 | I11: TOTAL VENTA: | J11: 0
A12: =IF(B12="","",VLOOKUP(B12,PROVEEDORES!$B:$C,2,FALSE)) | E12: 0
A13: PROPINA TRANSFERENCIA: | C13: =SUM(H2,J2) -> 0 | D13: ACUM. PROPINA TRANFERENCIA: | E13: =SUM(C13,I37)-C57 -> 0 | G13: DIFERENCIA PLANILLA VS CUADRE DE CAJA | I13: =+C20-(SUM(H9,J9)) -> 0
A14: PROPINA POR BANCO: | C14: =SUM(H3,J3) -> 0 | D14: ACUM. PROPINA BANCO: | E14: =SUM(C14,I38)-C58 -> 0
A15: PROPINA EN EFECTIVO: | C15: =SUM(H4,J4) -> 0 | D15: ACUM. PROPINA EFECTIVO: | E15: =SUM(C15,I39)-C59 -> 0 | G15: FACTURAS EN EFECTIVO: | I15: 0
A16: TOTAL EGRESOS: | C16: =SUM(E3:E12) -> 0 | D16: ACUMULADO TRANSFERENCIA: | E16: =SUM(C17,I40) -> 0 | G16: EFECTIVO: | I16: 0
A17: TRANSFERENCIA: | C17: =SUM(H6,J6) -> 0 | D17: ACUMULADO BANCO: | E17: =SUM(C18,I41) -> 0 | G17: TOTAL EFECTIVO REAL ACTUAL: | I17: =SUM(I15,I16) -> 0
A18: BANCO: | C18: =SUM(H7,J7) -> 0 | D18: TOTAL BANCO: | E18: =SUM(C18,I42)-(SUM(E36:E55)) -> 0 | G18: DIFERENCIA: | I18: =+I19-I17 -> 0
A19: EFECTIVO: | C19: =SUM(H8,J8) -> 0 | D19: TOTAL EFECTIVO: | E19: =SUM(C19,E20,E57:E59)-(SUM(E23:E34)) -> 0 | G19: EFECTIVO ACTUAL PLANILLA: | I19: =E19 -> 0
A20: TOTAL VENTA: | C20: =SUM(C16:C19) -> 0 | D20: EFECTIVO ANTERIOR: | E20: =+I43 -> 0
A21: EGRESO DE CAJA MAYOR | G21: CONTEO DE EFECTIVO
A22: NIT | B22: PROVEEDOR | C22: CONCEPTO | D22: DESCRIPCIÓN | E22: EFECTIVO | G22: DENOMINACIÓN | H22: CANTIDAD | I22: EFECTIVO
A23: =IF(B23="","",VLOOKUP(B23,PROVEEDORES!$B:$C,2,FALSE)) | E23: 0 | G23: MONEDAS DE 100 | H23: 0 | I23: =100*H23 -> 0
A24: =IF(B24="","",VLOOKUP(B24,PROVEEDORES!$B:$C,2,FALSE)) | E24: 0 | G24: MONEDAS DE 200 | H24: 0 | I24: =200*H24 -> 0
A25: =IF(B25="","",VLOOKUP(B25,PROVEEDORES!$B:$C,2,FALSE)) | E25: 0 | G25: MONEDAS DE 500 | H25: 0 | I25: =500*H25 -> 0
A26: =IF(B26="","",VLOOKUP(B26,PROVEEDORES!$B:$C,2,FALSE)) | E26: 0 | G26: MONEDAS DE 1.000 | H26: 0 | I26: =1000*H26 -> 0
A27: =IF(B27="","",VLOOKUP(B27,PROVEEDORES!$B:$C,2,FALSE)) | E27: 0 | G27: BILLETES DE 2.000 | H27: 0 | I27: =2000*H27 -> 0
A28: =IF(B28="","",VLOOKUP(B28,PROVEEDORES!$B:$C,2,FALSE)) | E28: 0 | G28: BILLETES DE 5.000 | H28: 0 | I28: =5000*H28 -> 0
A29: =IF(B29="","",VLOOKUP(B29,PROVEEDORES!$B:$C,2,FALSE)) | E29: 0 | G29: BILLETES DE 10.000 | H29: 0 | I29: =10000*H29 -> 0
A30: =IF(B30="","",VLOOKUP(B30,PROVEEDORES!$B:$C,2,FALSE)) | E30: 0 | G30: BILLETES DE 20.000 | H30: 0 | I30: =20000*H30 -> 0
A31: =IF(B31="","",VLOOKUP(B31,PROVEEDORES!$B:$C,2,FALSE)) | E31: 0 | G31: BILLETES DE 50.000 | H31: 0 | I31: =50000*H31 -> 0
A32: =IF(B32="","",VLOOKUP(B32,PROVEEDORES!$B:$C,2,FALSE)) | E32: 0 | G32: BILLETES DE 100.000 | H32: 0 | I32: =100000*H32 -> 0
A33: =IF(B33="","",VLOOKUP(B33,PROVEEDORES!$B:$C,2,FALSE)) | E33: 0 | G33: TOTAL EFECTIVO: | I33: =SUM(I23:I32) -> 0
A34: =IF(B34="","",VLOOKUP(B34,PROVEEDORES!$B:$C,2,FALSE)) | E34: 0 | G34: BASE: | I34: 0
A35: NIT | B35: PROVEEDOR | C35: CONCEPTO | D35: DESCRIPCIÓN | E35: BANCO | G35: TOTAL EFECTIVO MENOS LA BASE: | I35: =I33-I34 -> 0
A36: =IF(B36="","",VLOOKUP(B36,PROVEEDORES!$B:$C,2,FALSE)) | E36: 0
A37: =IF(B37="","",VLOOKUP(B37,PROVEEDORES!$B:$C,2,FALSE)) | E37: 0 | G37: ACUM. DE PROPINA TRANSFERENCIA: | I37: =+'5'!E13 -> 0
A38: =IF(B38="","",VLOOKUP(B38,PROVEEDORES!$B:$C,2,FALSE)) | E38: 0 | G38: ACUMULADO DE PROPINA EN BANCO: | I38: =+'5'!E14 -> 0
A39: =IF(B39="","",VLOOKUP(B39,PROVEEDORES!$B:$C,2,FALSE)) | E39: 0 | G39: ACUMULADO DE PROPINA POR EFECTIVO: | I39: =+'5'!E15 -> 0
A40: =IF(B40="","",VLOOKUP(B40,PROVEEDORES!$B:$C,2,FALSE)) | E40: 0 | G40: ACUMULADO DE TRANSFERENCIA: | I40: =+'5'!E16 -> 0
...

Sheet 7
A1: ='6'!A1+1 -> 7 | B1: =+'1'!B1 -> QUESO Y CAFÉ | D1: =+'6'!D1:E1+1 -> 46149 | G1: CUADRE DE CAJA MAÑANA | I1: CUADRE DE CAJA TARDE
A2: NIT | B2: PROVEEDOR | C2: CONCEPTO | D2: DESCRIPCIÓN | E2: VALOR | G2: PROP. TRANSF.: | H2: 0 | I2: PROP. TRANSF.: | J2: 0
A3: =IF(B3="","",VLOOKUP(B3,PROVEEDORES!$B:$C,2,FALSE)) | E3: 0 | G3: PROP. BANCO: | H3: 0 | I3: PROP. BANCO: | J3: 0
A4: =IF(B4="","",VLOOKUP(B4,PROVEEDORES!$B:$C,2,FALSE)) | E4: 0 | G4: PROP. EFECTIVO: | H4: 0 | I4: PROP. EFECTIVO: | J4: 0
A5: =IF(B5="","",VLOOKUP(B5,PROVEEDORES!$B:$C,2,FALSE)) | E5: 0 | G5: GASTO: | H5: 0 | I5: GASTO: | J5: 0
A6: =IF(B6="","",VLOOKUP(B6,PROVEEDORES!$B:$C,2,FALSE)) | E6: 0 | G6: TRANSFERENCIA: | H6: 0 | I6: TRANSFERENCIA: | J6: 0
A7: =IF(B7="","",VLOOKUP(B7,PROVEEDORES!$B:$C,2,FALSE)) | E7: 0 | G7: BANCO: | H7: 0 | I7: BANCO: | J7: 0
A8: =IF(B8="","",VLOOKUP(B8,PROVEEDORES!$B:$C,2,FALSE)) | E8: 0 | G8: EFECTIVO: | H8: 0 | I8: EFECTIVO: | J8: 0
A9: =IF(B9="","",VLOOKUP(B9,PROVEEDORES!$B:$C,2,FALSE)) | E9: 0 | G9: TOTAL: | H9: =SUM(H5:H8) -> 0 | I9: TOTAL: | J9: =SUM(J5:J8) -> 0
A10: =IF(B10="","",VLOOKUP(B10,PROVEEDORES!$B:$C,2,FALSE)) | E10: 0 | G10: DIFERENCIA: | H10: =+H11-H9 -> 0 | I10: DIFERENCIA: | J10: =+J11-J9 -> 0
A11: =IF(B11="","",VLOOKUP(B11,PROVEEDORES!$B:$C,2,FALSE)) | E11: 0 | G11: TOTAL VENTA: | H11: 0 | I11: TOTAL VENTA: | J11: 0
A12: =IF(B12="","",VLOOKUP(B12,PROVEEDORES!$B:$C,2,FALSE)) | E12: 0
A13: PROPINA TRANSFERENCIA: | C13: =SUM(H2,J2) -> 0 | D13: ACUM. PROPINA TRANFERENCIA: | E13: =SUM(C13,I37)-C57 -> 0 | G13: DIFERENCIA PLANILLA VS CUADRE DE CAJA | I13: =+C20-(SUM(H9,J9)) -> 0
A14: PROPINA POR BANCO: | C14: =SUM(H3,J3) -> 0 | D14: ACUM. PROPINA BANCO: | E14: =SUM(C14,I38)-C58 -> 0
A15: PROPINA EN EFECTIVO: | C15: =SUM(H4,J4) -> 0 | D15: ACUM. PROPINA EFECTIVO: | E15: =SUM(C15,I39)-C59 -> 0 | G15: FACTURAS EN EFECTIVO: | I15: 0
A16: TOTAL EGRESOS: | C16: =SUM(E3:E12) -> 0 | D16: ACUMULADO TRANSFERENCIA: | E16: =SUM(C17,I40) -> 0 | G16: EFECTIVO: | I16: 0
A17: TRANSFERENCIA: | C17: =SUM(H6,J6) -> 0 | D17: ACUMULADO BANCO: | E17: =SUM(C18,I41) -> 0 | G17: TOTAL EFECTIVO REAL ACTUAL: | I17: =SUM(I15,I16) -> 0
A18: BANCO: | C18: =SUM(H7,J7) -> 0 | D18: TOTAL BANCO: | E18: =SUM(C18,I42)-(SUM(E36:E55)) -> 0 | G18: DIFERENCIA: | I18: =+I19-I17 -> 0
A19: EFECTIVO: | C19: =SUM(H8,J8) -> 0 | D19: TOTAL EFECTIVO: | E19: =SUM(C19,E20,E57:E59)-(SUM(E23:E34)) -> 0 | G19: EFECTIVO ACTUAL PLANILLA: | I19: =E19 -> 0
A20: TOTAL VENTA: | C20: =SUM(C16:C19) -> 0 | D20: EFECTIVO ANTERIOR: | E20: =+I43 -> 0
A21: EGRESO DE CAJA MAYOR | G21: CONTEO DE EFECTIVO
A22: NIT | B22: PROVEEDOR | C22: CONCEPTO | D22: DESCRIPCIÓN | E22: EFECTIVO | G22: DENOMINACIÓN | H22: CANTIDAD | I22: EFECTIVO
A23: =IF(B23="","",VLOOKUP(B23,PROVEEDORES!$B:$C,2,FALSE)) | E23: 0 | G23: MONEDAS DE 100 | H23: 0 | I23: =100*H23 -> 0
A24: =IF(B24="","",VLOOKUP(B24,PROVEEDORES!$B:$C,2,FALSE)) | E24: 0 | G24: MONEDAS DE 200 | H24: 0 | I24: =200*H24 -> 0
A25: =IF(B25="","",VLOOKUP(B25,PROVEEDORES!$B:$C,2,FALSE)) | E25: 0 | G25: MONEDAS DE 500 | H25: 0 | I25: =500*H25 -> 0
A26: =IF(B26="","",VLOOKUP(B26,PROVEEDORES!$B:$C,2,FALSE)) | E26: 0 | G26: MONEDAS DE 1.000 | H26: 0 | I26: =1000*H26 -> 0
A27: =IF(B27="","",VLOOKUP(B27,PROVEEDORES!$B:$C,2,FALSE)) | E27: 0 | G27: BILLETES DE 2.000 | H27: 0 | I27: =2000*H27 -> 0
A28: =IF(B28="","",VLOOKUP(B28,PROVEEDORES!$B:$C,2,FALSE)) | E28: 0 | G28: BILLETES DE 5.000 | H28: 0 | I28: =5000*H28 -> 0
A29: =IF(B29="","",VLOOKUP(B29,PROVEEDORES!$B:$C,2,FALSE)) | E29: 0 | G29: BILLETES DE 10.000 | H29: 0 | I29: =10000*H29 -> 0
A30: =IF(B30="","",VLOOKUP(B30,PROVEEDORES!$B:$C,2,FALSE)) | E30: 0 | G30: BILLETES DE 20.000 | H30: 0 | I30: =20000*H30 -> 0
A31: =IF(B31="","",VLOOKUP(B31,PROVEEDORES!$B:$C,2,FALSE)) | E31: 0 | G31: BILLETES DE 50.000 | H31: 0 | I31: =50000*H31 -> 0
A32: =IF(B32="","",VLOOKUP(B32,PROVEEDORES!$B:$C,2,FALSE)) | E32: 0 | G32: BILLETES DE 100.000 | H32: 0 | I32: =100000*H32 -> 0
A33: =IF(B33="","",VLOOKUP(B33,PROVEEDORES!$B:$C,2,FALSE)) | E33: 0 | G33: TOTAL EFECTIVO: | I33: =SUM(I23:I32) -> 0
A34: =IF(B34="","",VLOOKUP(B34,PROVEEDORES!$B:$C,2,FALSE)) | E34: 0 | G34: BASE: | I34: 0
A35: NIT | B35: PROVEEDOR | C35: CONCEPTO | D35: DESCRIPCIÓN | E35: BANCO | G35: TOTAL EFECTIVO MENOS LA BASE: | I35: =I33-I34 -> 0
A36: =IF(B36="","",VLOOKUP(B36,PROVEEDORES!$B:$C,2,FALSE)) | E36: 0
A37: =IF(B37="","",VLOOKUP(B37,PROVEEDORES!$B:$C,2,FALSE)) | E37: 0 | G37: ACUM. DE PROPINA TRANSFERENCIA: | I37: =+'6'!E13 -> 0
A38: =IF(B38="","",VLOOKUP(B38,PROVEEDORES!$B:$C,2,FALSE)) | E38: 0 | G38: ACUMULADO DE PROPINA EN BANCO: | I38: =+'6'!E14 -> 0
A39: =IF(B39="","",VLOOKUP(B39,PROVEEDORES!$B:$C,2,FALSE)) | E39: 0 | G39: ACUMULADO DE PROPINA POR EFECTIVO: | I39: =+'6'!E15 -> 0
A40: =IF(B40="","",VLOOKUP(B40,PROVEEDORES!$B:$C,2,FALSE)) | E40: 0 | G40: ACUMULADO DE TRANSFERENCIA: | I40: =+'6'!E16 -> 0
...

Sheet 8
A1: ='7'!A1+1 -> 8 | B1: =+'1'!B1 -> QUESO Y CAFÉ | D1: =+'7'!D1:E1+1 -> 46150 | G1: CUADRE DE CAJA MAÑANA | I1: CUADRE DE CAJA TARDE
A2: NIT | B2: PROVEEDOR | C2: CONCEPTO | D2: DESCRIPCIÓN | E2: VALOR | G2: PROP. TRANSF.: | H2: 0 | I2: PROP. TRANSF.: | J2: 0
A3: =IF(B3="","",VLOOKUP(B3,PROVEEDORES!$B:$C,2,FALSE)) | E3: 0 | G3: PROP. BANCO: | H3: 0 | I3: PROP. BANCO: | J3: 0
A4: =IF(B4="","",VLOOKUP(B4,PROVEEDORES!$B:$C,2,FALSE)) | E4: 0 | G4: PROP. EFECTIVO: | H4: 0 | I4: PROP. EFECTIVO: | J4: 0
A5: =IF(B5="","",VLOOKUP(B5,PROVEEDORES!$B:$C,2,FALSE)) | E5: 0 | G5: GASTO: | H5: 0 | I5: GASTO: | J5: 0
A6: =IF(B6="","",VLOOKUP(B6,PROVEEDORES!$B:$C,2,FALSE)) | E6: 0 | G6: TRANSFERENCIA: | H6: 0 | I6: TRANSFERENCIA: | J6: 0
A7: =IF(B7="","",VLOOKUP(B7,PROVEEDORES!$B:$C,2,FALSE)) | E7: 0 | G7: BANCO: | H7: 0 | I7: BANCO: | J7: 0
A8: =IF(B8="","",VLOOKUP(B8,PROVEEDORES!$B:$C,2,FALSE)) | E8: 0 | G8: EFECTIVO: | H8: 0 | I8: EFECTIVO: | J8: 0
A9: =IF(B9="","",VLOOKUP(B9,PROVEEDORES!$B:$C,2,FALSE)) | E9: 0 | G9: TOTAL: | H9: =SUM(H5:H8) -> 0 | I9: TOTAL: | J9: =SUM(J5:J8) -> 0
A10: =IF(B10="","",VLOOKUP(B10,PROVEEDORES!$B:$C,2,FALSE)) | E10: 0 | G10: DIFERENCIA: | H10: =+H11-H9 -> 0 | I10: DIFERENCIA: | J10: =+J11-J9 -> 0
A11: =IF(B11="","",VLOOKUP(B11,PROVEEDORES!$B:$C,2,FALSE)) | E11: 0 | G11: TOTAL VENTA: | H11: 0 | I11: TOTAL VENTA: | J11: 0
A12: =IF(B12="","",VLOOKUP(B12,PROVEEDORES!$B:$C,2,FALSE)) | E12: 0
A13: PROPINA TRANSFERENCIA: | C13: =SUM(H2,J2) -> 0 | D13: ACUM. PROPINA TRANFERENCIA: | E13: =SUM(C13,I37)-C57 -> 0 | G13: DIFERENCIA PLANILLA VS CUADRE DE CAJA | I13: =+C20-(SUM(H9,J9)) -> 0
A14: PROPINA POR BANCO: | C14: =SUM(H3,J3) -> 0 | D14: ACUM. PROPINA BANCO: | E14: =SUM(C14,I38)-C58 -> 0
A15: PROPINA EN EFECTIVO: | C15: =SUM(H4,J4) -> 0 | D15: ACUM. PROPINA EFECTIVO: | E15: =SUM(C15,I39)-C59 -> 0 | G15: FACTURAS EN EFECTIVO: | I15: 0
A16: TOTAL EGRESOS: | C16: =SUM(E3:E12) -> 0 | D16: ACUMULADO TRANSFERENCIA: | E16: =SUM(C17,I40) -> 0 | G16: EFECTIVO: | I16: 0
A17: TRANSFERENCIA: | C17: =SUM(H6,J6) -> 0 | D17: ACUMULADO BANCO: | E17: =SUM(C18,I41) -> 0 | G17: TOTAL EFECTIVO REAL ACTUAL: | I17: =SUM(I15,I16) -> 0
A18: BANCO: | C18: =SUM(H7,J7) -> 0 | D18: TOTAL BANCO: | E18: =SUM(C18,I42)-(SUM(E36:E55)) -> 0 | G18: DIFERENCIA: | I18: =+I19-I17 -> 0
A19: EFECTIVO: | C19: =SUM(H8,J8) -> 0 | D19: TOTAL EFECTIVO: | E19: =SUM(C19,E20,E57:E59)-(SUM(E23:E34)) -> 0 | G19: EFECTIVO ACTUAL PLANILLA: | I19: =E19 -> 0
A20: TOTAL VENTA: | C20: =SUM(C16:C19) -> 0 | D20: EFECTIVO ANTERIOR: | E20: =+I43 -> 0
A21: EGRESO DE CAJA MAYOR | G21: CONTEO DE EFECTIVO
A22: NIT | B22: PROVEEDOR | C22: CONCEPTO | D22: DESCRIPCIÓN | E22: EFECTIVO | G22: DENOMINACIÓN | H22: CANTIDAD | I22: EFECTIVO
A23: =IF(B23="","",VLOOKUP(B23,PROVEEDORES!$B:$C,2,FALSE)) | E23: 0 | G23: MONEDAS DE 100 | H23: 0 | I23: =100*H23 -> 0
A24: =IF(B24="","",VLOOKUP(B24,PROVEEDORES!$B:$C,2,FALSE)) | E24: 0 | G24: MONEDAS DE 200 | H24: 0 | I24: =200*H24 -> 0
A25: =IF(B25="","",VLOOKUP(B25,PROVEEDORES!$B:$C,2,FALSE)) | E25: 0 | G25: MONEDAS DE 500 | H25: 0 | I25: =500*H25 -> 0
A26: =IF(B26="","",VLOOKUP(B26,PROVEEDORES!$B:$C,2,FALSE)) | E26: 0 | G26: MONEDAS DE 1.000 | H26: 0 | I26: =1000*H26 -> 0
A27: =IF(B27="","",VLOOKUP(B27,PROVEEDORES!$B:$C,2,FALSE)) | E27: 0 | G27: BILLETES DE 2.000 | H27: 0 | I27: =2000*H27 -> 0
A28: =IF(B28="","",VLOOKUP(B28,PROVEEDORES!$B:$C,2,FALSE)) | E28: 0 | G28: BILLETES DE 5.000 | H28: 0 | I28: =5000*H28 -> 0
A29: =IF(B29="","",VLOOKUP(B29,PROVEEDORES!$B:$C,2,FALSE)) | E29: 0 | G29: BILLETES DE 10.000 | H29: 0 | I29: =10000*H29 -> 0
A30: =IF(B30="","",VLOOKUP(B30,PROVEEDORES!$B:$C,2,FALSE)) | E30: 0 | G30: BILLETES DE 20.000 | H30: 0 | I30: =20000*H30 -> 0
A31: =IF(B31="","",VLOOKUP(B31,PROVEEDORES!$B:$C,2,FALSE)) | E31: 0 | G31: BILLETES DE 50.000 | H31: 0 | I31: =50000*H31 -> 0
A32: =IF(B32="","",VLOOKUP(B32,PROVEEDORES!$B:$C,2,FALSE)) | E32: 0 | G32: BILLETES DE 100.000 | H32: 0 | I32: =100000*H32 -> 0
A33: =IF(B33="","",VLOOKUP(B33,PROVEEDORES!$B:$C,2,FALSE)) | E33: 0 | G33: TOTAL EFECTIVO: | I33: =SUM(I23:I32) -> 0
A34: =IF(B34="","",VLOOKUP(B34,PROVEEDORES!$B:$C,2,FALSE)) | E34: 0 | G34: BASE: | I34: 0
A35: NIT | B35: PROVEEDOR | C35: CONCEPTO | D35: DESCRIPCIÓN | E35: BANCO | G35: TOTAL EFECTIVO MENOS LA BASE: | I35: =I33-I34 -> 0
A36: =IF(B36="","",VLOOKUP(B36,PROVEEDORES!$B:$C,2,FALSE)) | E36: 0
A37: =IF(B37="","",VLOOKUP(B37,PROVEEDORES!$B:$C,2,FALSE)) | E37: 0 | G37: ACUM. DE PROPINA TRANSFERENCIA: | I37: =+'7'!E13 -> 0
A38: =IF(B38="","",VLOOKUP(B38,PROVEEDORES!$B:$C,2,FALSE)) | E38: 0 | G38: ACUMULADO DE PROPINA EN BANCO: | I38: =+'7'!E14 -> 0
A39: =IF(B39="","",VLOOKUP(B39,PROVEEDORES!$B:$C,2,FALSE)) | E39: 0 | G39: ACUMULADO DE PROPINA POR EFECTIVO: | I39: =+'7'!E15 -> 0
A40: =IF(B40="","",VLOOKUP(B40,PROVEEDORES!$B:$C,2,FALSE)) | E40: 0 | G40: ACUMULADO DE TRANSFERENCIA: | I40: =+'7'!E16 -> 0
...

Sheet 9
A1: ='8'!A1+1 -> 9 | B1: =+'1'!B1 -> QUESO Y CAFÉ | D1: =+'8'!D1:E1+1 -> 46151 | G1: CUADRE DE CAJA MAÑANA | I1: CUADRE DE CAJA TARDE
A2: NIT | B2: PROVEEDOR | C2: CONCEPTO | D2: DESCRIPCIÓN | E2: VALOR | G2: PROP. TRANSF.: | H2: 0 | I2: PROP. TRANSF.: | J2: 0
A3: =IF(B3="","",VLOOKUP(B3,PROVEEDORES!$B:$C,2,FALSE)) | E3: 0 | G3: PROP. BANCO: | H3: 0 | I3: PROP. BANCO: | J3: 0
A4: =IF(B4="","",VLOOKUP(B4,PROVEEDORES!$B:$C,2,FALSE)) | E4: 0 | G4: PROP. EFECTIVO: | H4: 0 | I4: PROP. EFECTIVO: | J4: 0
A5: =IF(B5="","",VLOOKUP(B5,PROVEEDORES!$B:$C,2,FALSE)) | E5: 0 | G5: GASTO: | H5: 0 | I5: GASTO: | J5: 0
A6: =IF(B6="","",VLOOKUP(B6,PROVEEDORES!$B:$C,2,FALSE)) | E6: 0 | G6: TRANSFERENCIA: | H6: 0 | I6: TRANSFERENCIA: | J6: 0
A7: =IF(B7="","",VLOOKUP(B7,PROVEEDORES!$B:$C,2,FALSE)) | E7: 0 | G7: BANCO: | H7: 0 | I7: BANCO: | J7: 0
A8: =IF(B8="","",VLOOKUP(B8,PROVEEDORES!$B:$C,2,FALSE)) | E8: 0 | G8: EFECTIVO: | H8: 0 | I8: EFECTIVO: | J8: 0
A9: =IF(B9="","",VLOOKUP(B9,PROVEEDORES!$B:$C,2,FALSE)) | E9: 0 | G9: TOTAL: | H9: =SUM(H5:H8) -> 0 | I9: TOTAL: | J9: =SUM(J5:J8) -> 0
A10: =IF(B10="","",VLOOKUP(B10,PROVEEDORES!$B:$C,2,FALSE)) | E10: 0 | G10: DIFERENCIA: | H10: =+H11-H9 -> 0 | I10: DIFERENCIA: | J10: =+J11-J9 -> 0
A11: =IF(B11="","",VLOOKUP(B11,PROVEEDORES!$B:$C,2,FALSE)) | E11: 0 | G11: TOTAL VENTA: | H11: 0 | I11: TOTAL VENTA: | J11: 0
A12: =IF(B12="","",VLOOKUP(B12,PROVEEDORES!$B:$C,2,FALSE)) | E12: 0
A13: PROPINA TRANSFERENCIA: | C13: =SUM(H2,J2) -> 0 | D13: ACUM. PROPINA TRANFERENCIA: | E13: =SUM(C13,I37)-C57 -> 0 | G13: DIFERENCIA PLANILLA VS CUADRE DE CAJA | I13: =+C20-(SUM(H9,J9)) -> 0
A14: PROPINA POR BANCO: | C14: =SUM(H3,J3) -> 0 | D14: ACUM. PROPINA BANCO: | E14: =SUM(C14,I38)-C58 -> 0
A15: PROPINA EN EFECTIVO: | C15: =SUM(H4,J4) -> 0 | D15: ACUM. PROPINA EFECTIVO: | E15: =SUM(C15,I39)-C59 -> 0 | G15: FACTURAS EN EFECTIVO: | I15: 0
A16: TOTAL EGRESOS: | C16: =SUM(E3:E12) -> 0 | D16: ACUMULADO TRANSFERENCIA: | E16: =SUM(C17,I40) -> 0 | G16: EFECTIVO: | I16: 0
A17: TRANSFERENCIA: | C17: =SUM(H6,J6) -> 0 | D17: ACUMULADO BANCO: | E17: =SUM(C18,I41) -> 0 | G17: TOTAL EFECTIVO REAL ACTUAL: | I17: =SUM(I15,I16) -> 0
A18: BANCO: | C18: =SUM(H7,J7) -> 0 | D18: TOTAL BANCO: | E18: =SUM(C18,I42)-(SUM(E36:E55)) -> 0 | G18: DIFERENCIA: | I18: =+I19-I17 -> 0
A19: EFECTIVO: | C19: =SUM(H8,J8) -> 0 | D19: TOTAL EFECTIVO: | E19: =SUM(C19,E20,E57:E59)-(SUM(E23:E34)) -> 0 | G19: EFECTIVO ACTUAL PLANILLA: | I19: =E19 -> 0
A20: TOTAL VENTA: | C20: =SUM(C16:C19) -> 0 | D20: EFECTIVO ANTERIOR: | E20: =+I43 -> 0
A21: EGRESO DE CAJA MAYOR | G21: CONTEO DE EFECTIVO
A22: NIT | B22: PROVEEDOR | C22: CONCEPTO | D22: DESCRIPCIÓN | E22: EFECTIVO | G22: DENOMINACIÓN | H22: CANTIDAD | I22: EFECTIVO
A23: =IF(B23="","",VLOOKUP(B23,PROVEEDORES!$B:$C,2,FALSE)) | E23: 0 | G23: MONEDAS DE 100 | H23: 0 | I23: =100*H23 -> 0
A24: =IF(B24="","",VLOOKUP(B24,PROVEEDORES!$B:$C,2,FALSE)) | E24: 0 | G24: MONEDAS DE 200 | H24: 0 | I24: =200*H24 -> 0
A25: =IF(B25="","",VLOOKUP(B25,PROVEEDORES!$B:$C,2,FALSE)) | E25: 0 | G25: MONEDAS DE 500 | H25: 0 | I25: =500*H25 -> 0
A26: =IF(B26="","",VLOOKUP(B26,PROVEEDORES!$B:$C,2,FALSE)) | E26: 0 | G26: MONEDAS DE 1.000 | H26: 0 | I26: =1000*H26 -> 0
A27: =IF(B27="","",VLOOKUP(B27,PROVEEDORES!$B:$C,2,FALSE)) | E27: 0 | G27: BILLETES DE 2.000 | H27: 0 | I27: =2000*H27 -> 0
A28: =IF(B28="","",VLOOKUP(B28,PROVEEDORES!$B:$C,2,FALSE)) | E28: 0 | G28: BILLETES DE 5.000 | H28: 0 | I28: =5000*H28 -> 0
A29: =IF(B29="","",VLOOKUP(B29,PROVEEDORES!$B:$C,2,FALSE)) | E29: 0 | G29: BILLETES DE 10.000 | H29: 0 | I29: =10000*H29 -> 0
A30: =IF(B30="","",VLOOKUP(B30,PROVEEDORES!$B:$C,2,FALSE)) | E30: 0 | G30: BILLETES DE 20.000 | H30: 0 | I30: =20000*H30 -> 0
A31: =IF(B31="","",VLOOKUP(B31,PROVEEDORES!$B:$C,2,FALSE)) | E31: 0 | G31: BILLETES DE 50.000 | H31: 0 | I31: =50000*H31 -> 0
A32: =IF(B32="","",VLOOKUP(B32,PROVEEDORES!$B:$C,2,FALSE)) | E32: 0 | G32: BILLETES DE 100.000 | H32: 0 | I32: =100000*H32 -> 0
A33: =IF(B33="","",VLOOKUP(B33,PROVEEDORES!$B:$C,2,FALSE)) | E33: 0 | G33: TOTAL EFECTIVO: | I33: =SUM(I23:I32) -> 0
A34: =IF(B34="","",VLOOKUP(B34,PROVEEDORES!$B:$C,2,FALSE)) | E34: 0 | G34: BASE: | I34: 0
A35: NIT | B35: PROVEEDOR | C35: CONCEPTO | D35: DESCRIPCIÓN | E35: BANCO | G35: TOTAL EFECTIVO MENOS LA BASE: | I35: =I33-I34 -> 0
A36: =IF(B36="","",VLOOKUP(B36,PROVEEDORES!$B:$C,2,FALSE)) | E36: 0
A37: =IF(B37="","",VLOOKUP(B37,PROVEEDORES!$B:$C,2,FALSE)) | E37: 0 | G37: ACUM. DE PROPINA TRANSFERENCIA: | I37: =+'8'!E13 -> 0
A38: =IF(B38="","",VLOOKUP(B38,PROVEEDORES!$B:$C,2,FALSE)) | E38: 0 | G38: ACUMULADO DE PROPINA EN BANCO: | I38: =+'8'!E14 -> 0
A39: =IF(B39="","",VLOOKUP(B39,PROVEEDORES!$B:$C,2,FALSE)) | E39: 0 | G39: ACUMULADO DE PROPINA POR EFECTIVO: | I39: =+'8'!E15 -> 0
A40: =IF(B40="","",VLOOKUP(B40,PROVEEDORES!$B:$C,2,FALSE)) | E40: 0 | G40: ACUMULADO DE TRANSFERENCIA: | I40: =+'8'!E16 -> 0
...

Sheet 10
A1: ='9'!A1+1 -> 10 | B1: =+'1'!B1 -> QUESO Y CAFÉ | D1: =+'9'!D1:E1+1 -> 46152 | G1: CUADRE DE CAJA MAÑANA | I1: CUADRE DE CAJA TARDE
A2: NIT | B2: PROVEEDOR | C2: CONCEPTO | D2: DESCRIPCIÓN | E2: VALOR | G2: PROP. TRANSF.: | H2: 0 | I2: PROP. TRANSF.: | J2: 0
A3: =IF(B3="","",VLOOKUP(B3,PROVEEDORES!$B:$C,2,FALSE)) | E3: 0 | G3: PROP. BANCO: | H3: 0 | I3: PROP. BANCO: | J3: 0
A4: =IF(B4="","",VLOOKUP(B4,PROVEEDORES!$B:$C,2,FALSE)) | E4: 0 | G4: PROP. EFECTIVO: | H4: 0 | I4: PROP. EFECTIVO: | J4: 0
A5: =IF(B5="","",VLOOKUP(B5,PROVEEDORES!$B:$C,2,FALSE)) | E5: 0 | G5: GASTO: | H5: 0 | I5: GASTO: | J5: 0
A6: =IF(B6="","",VLOOKUP(B6,PROVEEDORES!$B:$C,2,FALSE)) | E6: 0 | G6: TRANSFERENCIA: | H6: 0 | I6: TRANSFERENCIA: | J6: 0
A7: =IF(B7="","",VLOOKUP(B7,PROVEEDORES!$B:$C,2,FALSE)) | E7: 0 | G7: BANCO: | H7: 0 | I7: BANCO: | J7: 0
A8: =IF(B8="","",VLOOKUP(B8,PROVEEDORES!$B:$C,2,FALSE)) | E8: 0 | G8: EFECTIVO: | H8: 0 | I8: EFECTIVO: | J8: 0
A9: =IF(B9="","",VLOOKUP(B9,PROVEEDORES!$B:$C,2,FALSE)) | E9: 0 | G9: TOTAL: | H9: =SUM(H5:H8) -> 0 | I9: TOTAL: | J9: =SUM(J5:J8) -> 0
A10: =IF(B10="","",VLOOKUP(B10,PROVEEDORES!$B:$C,2,FALSE)) | E10: 0 | G10: DIFERENCIA: | H10: =+H11-H9 -> 0 | I10: DIFERENCIA: | J10: =+J11-J9 -> 0
A11: =IF(B11="","",VLOOKUP(B11,PROVEEDORES!$B:$C,2,FALSE)) | E11: 0 | G11: TOTAL VENTA: | H11: 0 | I11: TOTAL VENTA: | J11: 0
A12: =IF(B12="","",VLOOKUP(B12,PROVEEDORES!$B:$C,2,FALSE)) | E12: 0
A13: PROPINA TRANSFERENCIA: | C13: =SUM(H2,J2) -> 0 | D13: ACUM. PROPINA TRANFERENCIA: | E13: =SUM(C13,I37)-C57 -> 0 | G13: DIFERENCIA PLANILLA VS CUADRE DE CAJA | I13: =+C20-(SUM(H9,J9)) -> 0
A14: PROPINA POR BANCO: | C14: =SUM(H3,J3) -> 0 | D14: ACUM. PROPINA BANCO: | E14: =SUM(C14,I38)-C58 -> 0
A15: PROPINA EN EFECTIVO: | C15: =SUM(H4,J4) -> 0 | D15: ACUM. PROPINA EFECTIVO: | E15: =SUM(C15,I39)-C59 -> 0 | G15: FACTURAS EN EFECTIVO: | I15: 0
A16: TOTAL EGRESOS: | C16: =SUM(E3:E12) -> 0 | D16: ACUMULADO TRANSFERENCIA: | E16: =SUM(C17,I40) -> 0 | G16: EFECTIVO: | I16: 0
A17: TRANSFERENCIA: | C17: =SUM(H6,J6) -> 0 | D17: ACUMULADO BANCO: | E17: =SUM(C18,I41) -> 0 | G17: TOTAL EFECTIVO REAL ACTUAL: | I17: =SUM(I15,I16) -> 0
A18: BANCO: | C18: =SUM(H7,J7) -> 0 | D18: TOTAL BANCO: | E18: =SUM(C18,I42)-(SUM(E36:E55)) -> 0 | G18: DIFERENCIA: | I18: =+I19-I17 -> 0
A19: EFECTIVO: | C19: =SUM(H8,J8) -> 0 | D19: TOTAL EFECTIVO: | E19: =SUM(C19,E20,E57:E59)-(SUM(E23:E34)) -> 0 | G19: EFECTIVO ACTUAL PLANILLA: | I19: =E19 -> 0
A20: TOTAL VENTA: | C20: =SUM(C16:C19) -> 0 | D20: EFECTIVO ANTERIOR: | E20: =+I43 -> 0
A21: EGRESO DE CAJA MAYOR | G21: CONTEO DE EFECTIVO
A22: NIT | B22: PROVEEDOR | C22: CONCEPTO | D22: DESCRIPCIÓN | E22: EFECTIVO | G22: DENOMINACIÓN | H22: CANTIDAD | I22: EFECTIVO
A23: =IF(B23="","",VLOOKUP(B23,PROVEEDORES!$B:$C,2,FALSE)) | E23: 0 | G23: MONEDAS DE 100 | H23: 0 | I23: =100*H23 -> 0
A24: =IF(B24="","",VLOOKUP(B24,PROVEEDORES!$B:$C,2,FALSE)) | E24: 0 | G24: MONEDAS DE 200 | H24: 0 | I24: =200*H24 -> 0
A25: =IF(B25="","",VLOOKUP(B25,PROVEEDORES!$B:$C,2,FALSE)) | E25: 0 | G25: MONEDAS DE 500 | H25: 0 | I25: =500*H25 -> 0
A26: =IF(B26="","",VLOOKUP(B26,PROVEEDORES!$B:$C,2,FALSE)) | E26: 0 | G26: MONEDAS DE 1.000 | H26: 0 | I26: =1000*H26 -> 0
A27: =IF(B27="","",VLOOKUP(B27,PROVEEDORES!$B:$C,2,FALSE)) | E27: 0 | G27: BILLETES DE 2.000 | H27: 0 | I27: =2000*H27 -> 0
A28: =IF(B28="","",VLOOKUP(B28,PROVEEDORES!$B:$C,2,FALSE)) | E28: 0 | G28: BILLETES DE 5.000 | H28: 0 | I28: =5000*H28 -> 0
A29: =IF(B29="","",VLOOKUP(B29,PROVEEDORES!$B:$C,2,FALSE)) | E29: 0 | G29: BILLETES DE 10.000 | H29: 0 | I29: =10000*H29 -> 0
A30: =IF(B30="","",VLOOKUP(B30,PROVEEDORES!$B:$C,2,FALSE)) | E30: 0 | G30: BILLETES DE 20.000 | H30: 0 | I30: =20000*H30 -> 0
A31: =IF(B31="","",VLOOKUP(B31,PROVEEDORES!$B:$C,2,FALSE)) | E31: 0 | G31: BILLETES DE 50.000 | H31: 0 | I31: =50000*H31 -> 0
A32: =IF(B32="","",VLOOKUP(B32,PROVEEDORES!$B:$C,2,FALSE)) | E32: 0 | G32: BILLETES DE 100.000 | H32: 0 | I32: =100000*H32 -> 0
A33: =IF(B33="","",VLOOKUP(B33,PROVEEDORES!$B:$C,2,FALSE)) | E33: 0 | G33: TOTAL EFECTIVO: | I33: =SUM(I23:I32) -> 0
A34: =IF(B34="","",VLOOKUP(B34,PROVEEDORES!$B:$C,2,FALSE)) | E34: 0 | G34: BASE: | I34: 0
A35: NIT | B35: PROVEEDOR | C35: CONCEPTO | D35: DESCRIPCIÓN | E35: BANCO | G35: TOTAL EFECTIVO MENOS LA BASE: | I35: =I33-I34 -> 0
A36: =IF(B36="","",VLOOKUP(B36,PROVEEDORES!$B:$C,2,FALSE)) | E36: 0
A37: =IF(B37="","",VLOOKUP(B37,PROVEEDORES!$B:$C,2,FALSE)) | E37: 0 | G37: ACUM. DE PROPINA TRANSFERENCIA: | I37: =+'9'!E13 -> 0
A38: =IF(B38="","",VLOOKUP(B38,PROVEEDORES!$B:$C,2,FALSE)) | E38: 0 | G38: ACUMULADO DE PROPINA EN BANCO: | I38: =+'9'!E14 -> 0
A39: =IF(B39="","",VLOOKUP(B39,PROVEEDORES!$B:$C,2,FALSE)) | E39: 0 | G39: ACUMULADO DE PROPINA POR EFECTIVO: | I39: =+'9'!E15 -> 0
A40: =IF(B40="","",VLOOKUP(B40,PROVEEDORES!$B:$C,2,FALSE)) | E40: 0 | G40: ACUMULADO DE TRANSFERENCIA: | I40: =+'9'!E16 -> 0
...

Sheet 11
A1: ='10'!A1+1 -> 11 | B1: =+'1'!B1 -> QUESO Y CAFÉ | D1: =+'10'!D1:E1+1 -> 46153 | G1: CUADRE DE CAJA MAÑANA | I1: CUADRE DE CAJA TARDE
A2: NIT | B2: PROVEEDOR | C2: CONCEPTO | D2: DESCRIPCIÓN | E2: VALOR | G2: PROP. TRANSF.: | H2: 0 | I2: PROP. TRANSF.: | J2: 0
A3: =IF(B3="","",VLOOKUP(B3,PROVEEDORES!$B:$C,2,FALSE)) | E3: 0 | G3: PROP. BANCO: | H3: 0 | I3: PROP. BANCO: | J3: 0
A4: =IF(B4="","",VLOOKUP(B4,PROVEEDORES!$B:$C,2,FALSE)) | E4: 0 | G4: PROP. EFECTIVO: | H4: 0 | I4: PROP. EFECTIVO: | J4: 0
A5: =IF(B5="","",VLOOKUP(B5,PROVEEDORES!$B:$C,2,FALSE)) | E5: 0 | G5: GASTO: | H5: 0 | I5: GASTO: | J5: 0
A6: =IF(B6="","",VLOOKUP(B6,PROVEEDORES!$B:$C,2,FALSE)) | E6: 0 | G6: TRANSFERENCIA: | H6: 0 | I6: TRANSFERENCIA: | J6: 0
A7: =IF(B7="","",VLOOKUP(B7,PROVEEDORES!$B:$C,2,FALSE)) | E7: 0 | G7: BANCO: | H7: 0 | I7: BANCO: | J7: 0
A8: =IF(B8="","",VLOOKUP(B8,PROVEEDORES!$B:$C,2,FALSE)) | E8: 0 | G8: EFECTIVO: | H8: 0 | I8: EFECTIVO: | J8: 0
A9: =IF(B9="","",VLOOKUP(B9,PROVEEDORES!$B:$C,2,FALSE)) | E9: 0 | G9: TOTAL: | H9: =SUM(H5:H8) -> 0 | I9: TOTAL: | J9: =SUM(J5:J8) -> 0
A10: =IF(B10="","",VLOOKUP(B10,PROVEEDORES!$B:$C,2,FALSE)) | E10: 0 | G10: DIFERENCIA: | H10: =+H11-H9 -> 0 | I10: DIFERENCIA: | J10: =+J11-J9 -> 0
A11: =IF(B11="","",VLOOKUP(B11,PROVEEDORES!$B:$C,2,FALSE)) | E11: 0 | G11: TOTAL VENTA: | H11: 0 | I11: TOTAL VENTA: | J11: 0
A12: =IF(B12="","",VLOOKUP(B12,PROVEEDORES!$B:$C,2,FALSE)) | E12: 0
A13: PROPINA TRANSFERENCIA: | C13: =SUM(H2,J2) -> 0 | D13: ACUM. PROPINA TRANFERENCIA: | E13: =SUM(C13,I37)-C57 -> 0 | G13: DIFERENCIA PLANILLA VS CUADRE DE CAJA | I13: =+C20-(SUM(H9,J9)) -> 0
A14: PROPINA POR BANCO: | C14: =SUM(H3,J3) -> 0 | D14: ACUM. PROPINA BANCO: | E14: =SUM(C14,I38)-C58 -> 0
A15: PROPINA EN EFECTIVO: | C15: =SUM(H4,J4) -> 0 | D15: ACUM. PROPINA EFECTIVO: | E15: =SUM(C15,I39)-C59 -> 0 | G15: FACTURAS EN EFECTIVO: | I15: 0
A16: TOTAL EGRESOS: | C16: =SUM(E3:E12) -> 0 | D16: ACUMULADO TRANSFERENCIA: | E16: =SUM(C17,I40) -> 0 | G16: EFECTIVO: | I16: 0
A17: TRANSFERENCIA: | C17: =SUM(H6,J6) -> 0 | D17: ACUMULADO BANCO: | E17: =SUM(C18,I41) -> 0 | G17: TOTAL EFECTIVO REAL ACTUAL: | I17: =SUM(I15,I16) -> 0
A18: BANCO: | C18: =SUM(H7,J7) -> 0 | D18: TOTAL BANCO: | E18: =SUM(C18,I42)-(SUM(E36:E55)) -> 0 | G18: DIFERENCIA: | I18: =+I19-I17 -> 0
A19: EFECTIVO: | C19: =SUM(H8,J8) -> 0 | D19: TOTAL EFECTIVO: | E19: =SUM(C19,E20,E57:E59)-(SUM(E23:E34)) -> 0 | G19: EFECTIVO ACTUAL PLANILLA: | I19: =E19 -> 0
A20: TOTAL VENTA: | C20: =SUM(C16:C19) -> 0 | D20: EFECTIVO ANTERIOR: | E20: =+I43 -> 0
A21: EGRESO DE CAJA MAYOR | G21: CONTEO DE EFECTIVO
A22: NIT | B22: PROVEEDOR | C22: CONCEPTO | D22: DESCRIPCIÓN | E22: EFECTIVO | G22: DENOMINACIÓN | H22: CANTIDAD | I22: EFECTIVO
A23: =IF(B23="","",VLOOKUP(B23,PROVEEDORES!$B:$C,2,FALSE)) | E23: 0 | G23: MONEDAS DE 100 | H23: 0 | I23: =100*H23 -> 0
A24: =IF(B24="","",VLOOKUP(B24,PROVEEDORES!$B:$C,2,FALSE)) | E24: 0 | G24: MONEDAS DE 200 | H24: 0 | I24: =200*H24 -> 0
A25: =IF(B25="","",VLOOKUP(B25,PROVEEDORES!$B:$C,2,FALSE)) | E25: 0 | G25: MONEDAS DE 500 | H25: 0 | I25: =500*H25 -> 0
A26: =IF(B26="","",VLOOKUP(B26,PROVEEDORES!$B:$C,2,FALSE)) | E26: 0 | G26: MONEDAS DE 1.000 | H26: 0 | I26: =1000*H26 -> 0
A27: =IF(B27="","",VLOOKUP(B27,PROVEEDORES!$B:$C,2,FALSE)) | E27: 0 | G27: BILLETES DE 2.000 | H27: 0 | I27: =2000*H27 -> 0
A28: =IF(B28="","",VLOOKUP(B28,PROVEEDORES!$B:$C,2,FALSE)) | E28: 0 | G28: BILLETES DE 5.000 | H28: 0 | I28: =5000*H28 -> 0
A29: =IF(B29="","",VLOOKUP(B29,PROVEEDORES!$B:$C,2,FALSE)) | E29: 0 | G29: BILLETES DE 10.000 | H29: 0 | I29: =10000*H29 -> 0
A30: =IF(B30="","",VLOOKUP(B30,PROVEEDORES!$B:$C,2,FALSE)) | E30: 0 | G30: BILLETES DE 20.000 | H30: 0 | I30: =20000*H30 -> 0
A31: =IF(B31="","",VLOOKUP(B31,PROVEEDORES!$B:$C,2,FALSE)) | E31: 0 | G31: BILLETES DE 50.000 | H31: 0 | I31: =50000*H31 -> 0
A32: =IF(B32="","",VLOOKUP(B32,PROVEEDORES!$B:$C,2,FALSE)) | E32: 0 | G32: BILLETES DE 100.000 | H32: 0 | I32: =100000*H32 -> 0
A33: =IF(B33="","",VLOOKUP(B33,PROVEEDORES!$B:$C,2,FALSE)) | E33: 0 | G33: TOTAL EFECTIVO: | I33: =SUM(I23:I32) -> 0
A34: =IF(B34="","",VLOOKUP(B34,PROVEEDORES!$B:$C,2,FALSE)) | E34: 0 | G34: BASE: | I34: 0
A35: NIT | B35: PROVEEDOR | C35: CONCEPTO | D35: DESCRIPCIÓN | E35: BANCO | G35: TOTAL EFECTIVO MENOS LA BASE: | I35: =I33-I34 -> 0
A36: =IF(B36="","",VLOOKUP(B36,PROVEEDORES!$B:$C,2,FALSE)) | E36: 0
A37: =IF(B37="","",VLOOKUP(B37,PROVEEDORES!$B:$C,2,FALSE)) | E37: 0 | G37: ACUM. DE PROPINA TRANSFERENCIA: | I37: =+'10'!E13 -> 0
A38: =IF(B38="","",VLOOKUP(B38,PROVEEDORES!$B:$C,2,FALSE)) | E38: 0 | G38: ACUMULADO DE PROPINA EN BANCO: | I38: =+'10'!E14 -> 0
A39: =IF(B39="","",VLOOKUP(B39,PROVEEDORES!$B:$C,2,FALSE)) | E39: 0 | G39: ACUMULADO DE PROPINA POR EFECTIVO: | I39: =+'10'!E15 -> 0
A40: =IF(B40="","",VLOOKUP(B40,PROVEEDORES!$B:$C,2,FALSE)) | E40: 0 | G40: ACUMULADO DE TRANSFERENCIA: | I40: =+'10'!E16 -> 0
...

Sheet 12
A1: ='11'!A1+1 -> 12 | B1: =+'1'!B1 -> QUESO Y CAFÉ | D1: =+'11'!D1:E1+1 -> 46154 | G1: CUADRE DE CAJA MAÑANA | I1: CUADRE DE CAJA TARDE
A2: NIT | B2: PROVEEDOR | C2: CONCEPTO | D2: DESCRIPCIÓN | E2: VALOR | G2: PROP. TRANSF.: | H2: 0 | I2: PROP. TRANSF.: | J2: 0
A3: =IF(B3="","",VLOOKUP(B3,PROVEEDORES!$B:$C,2,FALSE)) | E3: 0 | G3: PROP. BANCO: | H3: 0 | I3: PROP. BANCO: | J3: 0
A4: =IF(B4="","",VLOOKUP(B4,PROVEEDORES!$B:$C,2,FALSE)) | E4: 0 | G4: PROP. EFECTIVO: | H4: 0 | I4: PROP. EFECTIVO: | J4: 0
A5: =IF(B5="","",VLOOKUP(B5,PROVEEDORES!$B:$C,2,FALSE)) | E5: 0 | G5: GASTO: | H5: 0 | I5: GASTO: | J5: 0
A6: =IF(B6="","",VLOOKUP(B6,PROVEEDORES!$B:$C,2,FALSE)) | E6: 0 | G6: TRANSFERENCIA: | H6: 0 | I6: TRANSFERENCIA: | J6: 0
A7: =IF(B7="","",VLOOKUP(B7,PROVEEDORES!$B:$C,2,FALSE)) | E7: 0 | G7: BANCO: | H7: 0 | I7: BANCO: | J7: 0
A8: =IF(B8="","",VLOOKUP(B8,PROVEEDORES!$B:$C,2,FALSE)) | E8: 0 | G8: EFECTIVO: | H8: 0 | I8: EFECTIVO: | J8: 0
A9: =IF(B9="","",VLOOKUP(B9,PROVEEDORES!$B:$C,2,FALSE)) | E9: 0 | G9: TOTAL: | H9: =SUM(H5:H8) -> 0 | I9: TOTAL: | J9: =SUM(J5:J8) -> 0
A10: =IF(B10="","",VLOOKUP(B10,PROVEEDORES!$B:$C,2,FALSE)) | E10: 0 | G10: DIFERENCIA: | H10: =+H11-H9 -> 0 | I10: DIFERENCIA: | J10: =+J11-J9 -> 0
A11: =IF(B11="","",VLOOKUP(B11,PROVEEDORES!$B:$C,2,FALSE)) | E11: 0 | G11: TOTAL VENTA: | H11: 0 | I11: TOTAL VENTA: | J11: 0
A12: =IF(B12="","",VLOOKUP(B12,PROVEEDORES!$B:$C,2,FALSE)) | E12: 0
A13: PROPINA TRANSFERENCIA: | C13: =SUM(H2,J2) -> 0 | D13: ACUM. PROPINA TRANFERENCIA: | E13: =SUM(C13,I37)-C57 -> 0 | G13: DIFERENCIA PLANILLA VS CUADRE DE CAJA | I13: =+C20-(SUM(H9,J9)) -> 0
A14: PROPINA POR BANCO: | C14: =SUM(H3,J3) -> 0 | D14: ACUM. PROPINA BANCO: | E14: =SUM(C14,I38)-C58 -> 0
A15: PROPINA EN EFECTIVO: | C15: =SUM(H4,J4) -> 0 | D15: ACUM. PROPINA EFECTIVO: | E15: =SUM(C15,I39)-C59 -> 0 | G15: FACTURAS EN EFECTIVO: | I15: 0
A16: TOTAL EGRESOS: | C16: =SUM(E3:E12) -> 0 | D16: ACUMULADO TRANSFERENCIA: | E16: =SUM(C17,I40) -> 0 | G16: EFECTIVO: | I16: 0
A17: TRANSFERENCIA: | C17: =SUM(H6,J6) -> 0 | D17: ACUMULADO BANCO: | E17: =SUM(C18,I41) -> 0 | G17: TOTAL EFECTIVO REAL ACTUAL: | I17: =SUM(I15,I16) -> 0
A18: BANCO: | C18: =SUM(H7,J7) -> 0 | D18: TOTAL BANCO: | E18: =SUM(C18,I42)-(SUM(E36:E55)) -> 0 | G18: DIFERENCIA: | I18: =+I19-I17 -> 0
A19: EFECTIVO: | C19: =SUM(H8,J8) -> 0 | D19: TOTAL EFECTIVO: | E19: =SUM(C19,E20,E57:E59)-(SUM(E23:E34)) -> 0 | G19: EFECTIVO ACTUAL PLANILLA: | I19: =E19 -> 0
A20: TOTAL VENTA: | C20: =SUM(C16:C19) -> 0 | D20: EFECTIVO ANTERIOR: | E20: =+I43 -> 0
A21: EGRESO DE CAJA MAYOR | G21: CONTEO DE EFECTIVO
A22: NIT | B22: PROVEEDOR | C22: CONCEPTO | D22: DESCRIPCIÓN | E22: EFECTIVO | G22: DENOMINACIÓN | H22: CANTIDAD | I22: EFECTIVO
A23: =IF(B23="","",VLOOKUP(B23,PROVEEDORES!$B:$C,2,FALSE)) | E23: 0 | G23: MONEDAS DE 100 | H23: 0 | I23: =100*H23 -> 0
A24: =IF(B24="","",VLOOKUP(B24,PROVEEDORES!$B:$C,2,FALSE)) | E24: 0 | G24: MONEDAS DE 200 | H24: 0 | I24: =200*H24 -> 0
A25: =IF(B25="","",VLOOKUP(B25,PROVEEDORES!$B:$C,2,FALSE)) | E25: 0 | G25: MONEDAS DE 500 | H25: 0 | I25: =500*H25 -> 0
A26: =IF(B26="","",VLOOKUP(B26,PROVEEDORES!$B:$C,2,FALSE)) | E26: 0 | G26: MONEDAS DE 1.000 | H26: 0 | I26: =1000*H26 -> 0
A27: =IF(B27="","",VLOOKUP(B27,PROVEEDORES!$B:$C,2,FALSE)) | E27: 0 | G27: BILLETES DE 2.000 | H27: 0 | I27: =2000*H27 -> 0
A28: =IF(B28="","",VLOOKUP(B28,PROVEEDORES!$B:$C,2,FALSE)) | E28: 0 | G28: BILLETES DE 5.000 | H28: 0 | I28: =5000*H28 -> 0
A29: =IF(B29="","",VLOOKUP(B29,PROVEEDORES!$B:$C,2,FALSE)) | E29: 0 | G29: BILLETES DE 10.000 | H29: 0 | I29: =10000*H29 -> 0
A30: =IF(B30="","",VLOOKUP(B30,PROVEEDORES!$B:$C,2,FALSE)) | E30: 0 | G30: BILLETES DE 20.000 | H30: 0 | I30: =20000*H30 -> 0
A31: =IF(B31="","",VLOOKUP(B31,PROVEEDORES!$B:$C,2,FALSE)) | E31: 0 | G31: BILLETES DE 50.000 | H31: 0 | I31: =50000*H31 -> 0
A32: =IF(B32="","",VLOOKUP(B32,PROVEEDORES!$B:$C,2,FALSE)) | E32: 0 | G32: BILLETES DE 100.000 | H32: 0 | I32: =100000*H32 -> 0
A33: =IF(B33="","",VLOOKUP(B33,PROVEEDORES!$B:$C,2,FALSE)) | E33: 0 | G33: TOTAL EFECTIVO: | I33: =SUM(I23:I32) -> 0
A34: =IF(B34="","",VLOOKUP(B34,PROVEEDORES!$B:$C,2,FALSE)) | E34: 0 | G34: BASE: | I34: 0
A35: NIT | B35: PROVEEDOR | C35: CONCEPTO | D35: DESCRIPCIÓN | E35: BANCO | G35: TOTAL EFECTIVO MENOS LA BASE: | I35: =I33-I34 -> 0
A36: =IF(B36="","",VLOOKUP(B36,PROVEEDORES!$B:$C,2,FALSE)) | E36: 0
A37: =IF(B37="","",VLOOKUP(B37,PROVEEDORES!$B:$C,2,FALSE)) | E37: 0 | G37: ACUM. DE PROPINA TRANSFERENCIA: | I37: =+'11'!E13 -> 0
A38: =IF(B38="","",VLOOKUP(B38,PROVEEDORES!$B:$C,2,FALSE)) | E38: 0 | G38: ACUMULADO DE PROPINA EN BANCO: | I38: =+'11'!E14 -> 0
A39: =IF(B39="","",VLOOKUP(B39,PROVEEDORES!$B:$C,2,FALSE)) | E39: 0 | G39: ACUMULADO DE PROPINA POR EFECTIVO: | I39: =+'11'!E15 -> 0
A40: =IF(B40="","",VLOOKUP(B40,PROVEEDORES!$B:$C,2,FALSE)) | E40: 0 | G40: ACUMULADO DE TRANSFERENCIA: | I40: =+'11'!E16 -> 0
...

Sheet 13
A1: ='12'!A1+1 -> 13 | B1: =+'1'!B1 -> QUESO Y CAFÉ | D1: =+'12'!D1:E1+1 -> 46155 | G1: CUADRE DE CAJA MAÑANA | I1: CUADRE DE CAJA TARDE
A2: NIT | B2: PROVEEDOR | C2: CONCEPTO | D2: DESCRIPCIÓN | E2: VALOR | G2: PROP. TRANSF.: | H2: 0 | I2: PROP. TRANSF.: | J2: 0
A3: =IF(B3="","",VLOOKUP(B3,PROVEEDORES!$B:$C,2,FALSE)) | E3: 0 | G3: PROP. BANCO: | H3: 0 | I3: PROP. BANCO: | J3: 0
A4: =IF(B4="","",VLOOKUP(B4,PROVEEDORES!$B:$C,2,FALSE)) | E4: 0 | G4: PROP. EFECTIVO: | H4: 0 | I4: PROP. EFECTIVO: | J4: 0
A5: =IF(B5="","",VLOOKUP(B5,PROVEEDORES!$B:$C,2,FALSE)) | E5: 0 | G5: GASTO: | H5: 0 | I5: GASTO: | J5: 0
A6: =IF(B6="","",VLOOKUP(B6,PROVEEDORES!$B:$C,2,FALSE)) | E6: 0 | G6: TRANSFERENCIA: | H6: 0 | I6: TRANSFERENCIA: | J6: 0
A7: =IF(B7="","",VLOOKUP(B7,PROVEEDORES!$B:$C,2,FALSE)) | E7: 0 | G7: BANCO: | H7: 0 | I7: BANCO: | J7: 0
A8: =IF(B8="","",VLOOKUP(B8,PROVEEDORES!$B:$C,2,FALSE)) | E8: 0 | G8: EFECTIVO: | H8: 0 | I8: EFECTIVO: | J8: 0
